9 Bad status for: u'c:\\workspace\\\ub179\ud654\\cakd3\\.git\\objects\\c8\\2a862488b8ab088d93da254bca6752b9e502e0'
2021-07-21 18:36:38,062 +0900 WARNING pid=12760 10092:Batcher         overlay_status.py:289 Bad status for: u'c:\\workspace\\\ub179\ud654\\cakd3\\.git\\objects\\c8\\bfa4b5939b202f5c84817a1f5af5c794104e77'
2021-07-21 18:36:38,062 +0900 WARNING pid=12760 10092:Batcher         overlay_status.py:289 Bad status for: u'c:\\workspace\\\ub179\ud654\\cakd3\\.git\\objects\\c9'
2021-07-21 18:36:38,062 +0900 WARNING pid=12760 10092:Batcher         overlay_status.py:289 Bad status for: u'c:\\workspace\\\ub179\ud654\\cakd3\\.git\\objects\\c9\\db736c1e6b9710fc4424781c401290110f680a'
2021-07-21 18:36:38,062 +0900 WARNING pid=12760 10092:Batcher         overlay_status.py:289 Bad status for: u'c:\\workspace\\\ub179\ud654\\cakd3\\.git\\objects\\c9\\12e03d7a6883dbbf2cb2bd6f1515100024678d'
2021-07-21 18:36:38,062 +0900 WARNING pid=12760 10092:Batcher         overlay_status.py:289 Bad status for: u'c:\\workspace\\\ub179\ud654\\cakd3\\.git\\objects\\c9\\6df3157c6c060fbcee3b9ad4044fab2eff7586'
2021-07-21 18:36:38,063 +0900 WARNING pid=12760 10092:Batcher         overlay_status.py:289 Bad status for: u'c:\\workspace\\\ub179\ud654\\cakd3\\.git\\objects\\ce'
2021-07-21 18:36:38,063 +0900 WARNING pid=12760 10092:Batcher         overlay_status.py:289 Bad status for: u'c:\\workspace\\\ub179\ud654\\cakd3\\.git\\objects\\ce\\2c4cd3eaa95c1853c657824310087e888a00d3'
2021-07-21 18:36:38,063 +0900 WARNING pid=12760 10092:Batcher         overlay_status.py:289 Bad status for: u'c:\\workspace\\\ub179\ud654\\cakd3\\.git\\objects\\ce\\8f53cd0e3c94f1839c07c2eb08195ebc423ec1'
2021-07-21 18:36:38,063 +0900 WARNING pid=12760 10092:Batcher         overlay_status.py:289 Bad status for: u'c:\\workspace\\\ub179\ud654\\cakd3\\.git\\objects\\ce\\20cda72a874d778587ba120dc3fac36a5bea6c'
2021-07-21 18:36:38,063 +0900 WARNING pid=12760 10092:Batcher         overlay_status.py:289 Bad status for: u'c:\\workspace\\\ub179\ud654\\cakd3\\.git\\objects\\cf'
2021-07-21 18:36:38,063 +0900 WARNING pid=12760 10092:Batcher         overlay_status.py:289 Bad status for: u'c:\\workspace\\\ub179\ud654\\cakd3\\.git\\objects\\cf\\ce78658b1a74d833de7c3fba681bb62304478d'
2021-07-21 18:36:38,063 +0900 WARNING pid=12760 10092:Batcher         overlay_status.py:289 Bad status for: u'c:\\workspace\\\ub179\ud654\\cakd3\\.git\\objects\\cb'
2021-07-21 18:36:38,063 +0900 WARNING pid=12760 10092:Batcher         overlay_status.py:289 Bad status for: u'c:\\workspace\\\ub179\ud654\\cakd3\\.git\\objects\\cb\\0fd54b4016f0b39f011bace42a461cc219b472'
2021-07-21 18:36:38,063 +0900 WARNING pid=12760 10092:Batcher         overlay_status.py:289 Bad status for: u'c:\\workspace\\\ub179\ud654\\cakd3\\.git\\objects\\cb\\5d8535e3d25c06ec7090ab677561895803fe2d'
2021-07-21 18:36:38,063 +0900 WARNING pid=12760 10092:Batcher         overlay_status.py:289 Bad status for: u'c:\\workspace\\\ub179\ud654\\cakd3\\.git\\objects\\cb\\0e596577b9e2e8c1934973e55ca18579fc08e6'
2021-07-21 18:36:38,065 +0900 WARNING pid=12760 10092:Batcher         overlay_status.py:289 Bad status for: u'c:\\workspace\\\ub179\ud654\\cakd3\\.git\\objects\\cc'
2021-07-21 18:36:38,065 +0900 WARNING pid=12760 10092:Batcher         overlay_status.py:289 Bad status for: u'c:\\workspace\\\ub179\ud654\\cakd3\\.git\\objects\\cc\\67606f330b4e5b4d643ce3adadee13122a081c'
2021-07-21 18:36:38,065 +0900 WARNING pid=12760 10092:Batcher         overlay_status.py:289 Bad status for: u'c:\\workspace\\\ub179\ud654\\cakd3\\.git\\objects\\cc\\f04fc038a5430900cf487f5ad25fed62c09456'
2021-07-21 18:36:38,065 +0900 WARNING pid=12760 10092:Batcher         overlay_status.py:289 Bad status for: u'c:\\workspace\\\ub179\ud654\\cakd3\\.git\\objects\\cc\\f533c0d37d340b08afdd1f17fa134631d49a0c'
2021-07-21 18:36:38,065 +0900 WARNING pid=12760 10092:Batcher         overlay_status.py:289 Bad status for: u'c:\\workspace\\\ub179\ud654\\cakd3\\.git\\objects\\cc\\cdbbbff2fbeaefd90315d4333a78d0c4ccf6eb'
2021-07-21 18:36:38,065 +0900 WARNING pid=12760 10092:Batchelume='serial:3188545052'), is_folder=False, modified=1626858011, size=10720, generator_module=Generator.LOCAL_EVENT_GENERATOR, shared=False, hash=240806528, row_id=2090) Because of exception: ClientDetectedCloudStorageQuotaExceeded: 'File size (10720) exceeds available space (-43553) on server.', recovery targets: set([LocalID(inode=1125899906907871L, volume='serial:3188545052'), LocalID(inode=1125899906907870L, volume='serial:3188545052')])
2021-07-21 18:38:37,733 +0900 INFO pid=12760 12460:Worker-2        change_buffer_entry.py:215 Replacing entry in change buffer: ChangeBufferEntry(state=IN_PROGRESS, fschange=FSChange(Direction.UPLOAD, Action.CREATE, local_id=LocalID(inode=1125899906907871L, volume='serial:3188545052'), path=u'\\\\?\\C:\\workspace\\\ub179\ud654\\cakd3\\.git\\objects\\d6', name=u'feb35447f5ac8fb695d2d1a30484c000df606a', parent_local_id=LocalID(inode=1125899906907870L, volume='serial:3188545052'), is_folder=False, modified=1626858011, size=10720, generator_module=Generator.LOCAL_EVENT_GENERATOR, shared=False, row_id=2090), time=190560.359, row_id=1903)->ChangeBufferEntry(state=BLACKLISTED, fschange=FSChange(Direction.UPLOAD, Action.CREATE, local_id=LocalID(inode=1125899906907871L, volume='serial:3188545052'), path=u'\\\\?\\C:\\workspace\\\ub179\ud654\\cakd3\\.git\\objects\\d6', name=u'feb35447f5ac8fb695d2d1a30484c000df606a', parent_local_id=LocalID(inode=1125899906907870L, volume='serial:3188545052'), is_folder=False, modified=1626858011, size=10720, generator_module=Generator.LOCAL_EVENT_GENERATOR, shared=False, row_id=2090), blacklist_info=BlacklistInfoSub(key=u'\\\\?\\C:\\workspace\\\ub179\ud654\\cakd3\\.git\\objects\\d6\\feb35447f5ac8fb695d2d1a30484c000df606a', fullname=u'\\\\?\\C:\\workspace\\\ub179\ud654\\cakd3\\.git\\objects\\d6\\feb35447f5ac8fb695d2d1a30484c000df606a', direction=<Direction.UPLOAD: 'UPLOAD'>, failure=ClientDetectedCloudStorageQuotaExceeded(), entry_time=190690.734, url=None, is_folder=False, action=<Action.CREATE: 'CREATE'>), time=190560.359, row_id=1903)
2021-07-21 18:38:37,778 +0900 ERROR pid=12760 12468:Worker-1        blacklist.py:286 The following request has been blacklisted FSChange(Direction.UPLOAD, Action.CREATE, local_id=LocalID(inode=1407374883618529L, volume='serial:3188545052'), path=u'\\\\?\\C:\\workspace\\\ub179\ud654\\cakd3\\.git\\objects\\d7', name=u'089d5e9dc5080d67d348d1667c8f22a1adfd71', parent_local_id=LocalID(inode=844424930197216L, volume='serial:3188545052'), is_folder=False, modified=1626858121, size=182, generator_module=Generator.LOCAL_EVENT_GENERATOR, shared=False, hash=58296869, row_id=2092) Because of exception: ClientDetectedCloudStorageQuotaExceeded: 'File size (182) exceeds available space (-43553) on server.', recovery targets: set([LocalID(inode=844424930197216L, volume='serial:3188545052'), LocalID(inode=1407374883618529L, volume='serial:3188545052')])
2021-07-21 18:38:37,778 +0900 INFO pid=12760 12468:Worker-1        change_buffer_entry.py:215 Replacing entry in change buffer: ChangeBufferEntry(state=IN_PROGRESS, fschange=FSChange(Direction.UPLOAD, Action.CREATE, local_id=LocalID(inode=1407374883618529L, volume='serial:3188545052'), path=u'\\\\?\\C:\\workspace\\\ub179\ud654\\cakd3\\.git\\objects\\d7', name=u'089d5e9dc5080d67d348d1667c8f22a1adfd71', parent_local_id=LocalID(inode=844424930197216L, volume='serial:3188545052'), is_folder=False, modified=1626858121, size=182, generator_module=Generator.LOCAL_EVENT_GENERATOR, shared=False, row_id=2092), time=190560.531, row_id=1905)->ChangeBufferEntry(state=BLACKLISTED, fschange=FSChange(Direction.UPLOAD, Action.CREATE, local_id=LocalID(inode=1407374883618529L, volume='serial:3188545052'), path=u'\\\\?\\C:\\workspace\\\ub179\ud654\\cakd3\\.git\\objects\\d7', name=u'089d5e9dc5080d67d348d1667c8f22a1adfd71', parent_local_id=LocalID(inode=844424930197216L, volume='serial:3188545052'), is_folder=False, modified=1626858121, size=182, generator_module=Generator.LOCAL_EVENT_GENERATOR, shared=False, row_id=2092), blacklist_info=BlacklistInfoSub(key=u'\\\\?\\C:\\workspace\\\ub179\ud654\\cakd3\\.git\\objects\\d7\\089d5e9dc5080d67d348d1667c8f22a1adfd71', fullname=u'\\\\?\\C:\\workspace\\\ub179\ud654\\cakd3\\.git\\objects\\d7\\089d5e9dc5080d67d348d1667c8f22a1adfd71', direction=<Direction.UPLOAD: 'UPLOAD'>, failure=ClientDetectedCloudStorageQuotaExceeded(), entry_time=190690.78100000002, url=None, is_folder=False, action=<Action.CREATE: 'CREATE'>), time=190560.531, row_id=1905)
2021-07-21 18:38:37,838 +0900 INFO pid=12760 10252:Worker-0        workers.py:192 Worker starting on [FSChange(Direction.UPLOAD, Action.CREATE, local_id=LocalID(inode=1407374883618530L, volume='serial:3188545052'), path=u'\\\\?\\C:\\workspace\\\ub179\ud654\\cakd3\\.git\\objects\\d7', name=u'e7903d08731a61fc9b560177c33a67c99b1d4c', parent_local_id=LocalID(inode=844424930197216L, volume='serial:3188545052'), is_folder=False, modified=1625291357, size=23159, generator_module=Generator.LOCAL_EVENT_GENERATOR, shared=False, hash=-1051127486, row_id=2093)]
2021-07-21 18:38:37,839 +0900 INFO pid=12760 10252:Worker-0        doc_id_provider.py:126 Returning doc ID '16kbIBeF3M5erO7bWAH1r44Up2r7Wd5H_'. 2865 IDs left in store.
2021-07-21 18:38:37,839 +0900 INFO pid=12760 10252:Worker-0        snapshot_sqlite.py:647 Adding pre_mapping local_id=LocalID(inode=1407374883618530L, volume='serial:3188545052'), doc_id=16kbIBeF3M5erO7bWAH1r44Up2r7Wd5H_
2021-07-21 18:38:37,842 +0900 ERROR pid=12760 10252:Worker-0        workers.py:234 Exception while processing change [FSChange(Direction.UPLOAD, Action.CREATE, local_id=LocalID(inode=1407374883618530L, volume='serial:3188545052'), path=u'\\\\?\\C:\\workspace\\\ub179\ud654\\cakd3\\.git\\objects\\d7', name=u'e7903d08731a61fc9b560177c33a67c99b1d4c', parent_local_id=LocalID(inode=844424930197216L, volume='serial:3188545052'), is_folder=False, modified=1625291357, size=23159, generator_module=Generator.LOCAL_EVENT_GENERATOR, shared=False, hash=-1051127486, row_id=2093)]
Traceback (most recent call last):
  File "common\workers.py", line 201, in Process
  File "common\persistence\sqlite.py", line 141, in Wrapper
  File "common\workers.py", line 359, in _ProcessChanges
  File "common\worker\uploads.py", line 958, in Execute
  File "common\worker\uploads.py", line 1108, in _UploadCreate
  File "common\worker\workers_helper.py", line 406, in CreateCloudFile
  File "common\worker\workers_helper.py", line 372, in EnforceRemainingQuota
ClientDetectedCloudStorageQuotaExceeded: ClientDetectedCloudStorageQuotaExceeded: 'File size (23159) exceeds available space (-43553) on server.', recovery targets: set([])
2021-07-21 18:38:37,842 +0900 WARNING pid=12760 10252:Worker-0        workers.py:422 Setting recovery_targets for all changes. ClientDetectedCloudStorageQuotaExceeded: 'File size (23159) exceeds available space (-43553) on server.', recovery targets: set([])
2021-07-21 18:38:37,844 +0900 ERROR pid=12760 10252:Worker-0        fatal_exceptions.py:69 Ignoring non-fatal error: ClientDetectedCloudStorageQuotaExceeded: ClientDetectedCloudStorageQuotaExceeded: 'File size (23159) exceeds available space (-43553) on server.', recovery targets: set([LocalID(inode=844424930197216L, volume='serial:3188545052'), LocalID(inode=1407374883618530L, volume='serial:3188545052')]), Traceback:
  File "common\workers.py", line 201, in Process
  File "common\persistence\sqlite.py", line 141, in Wrapper
  File "common\workers.py", line 359, in _ProcessChanges
  File "common\worker\uploads.py", line 958, in Execute
  File "common\worker\uploads.py", line 1108, in _UploadCreate
  File "common\worker\workers_helper.py", line 406, in CreateCloudFile
  File "common\worker\workers_helper.py", line 372, in EnforceRemainingQuota

2021-07-21 18:38:37,855 +0900 ERROR pid=12760 10252:Worker-0        blacklist.py:286 The following request has been blacklisted FSChange(Direction.UPLOAD, Action.CREATE, local_id=LocalID(inode=1407374883618530L, volume='serial:3188545052'), path=u'\\\\?\\C:\\workspace\\\ub179\ud654\\cakd3\\.git\\objects\\d7', name=u'e7903d08731a61fc9b560177c33a67c99b1d4c', parent_local_id=LocalID(inode=844424930197216L, volume='serial:3188545052'), is_folder=False, modified=1625291357, size=23159, generator_module=Generator.LOCAL_EVENT_GENERATOR, shared=False, hash=-1051127486, row_id=2093) Because of exception: ClientDetectedCloudStorageQuotaExceeded: 'File size (23159) exceeds available space (-43553) on server.', recovery targets: set([LocalID(inode=844424930197216L, volume='serial:3188545052'), LocalID(inode=1407374883618530L, volume='serial:3188545052')])
2021-07-21 18:38:37,855 +0900 INFO pid=12760 10252:Worker-0        change_buffer_entry.py:215 Replacing entry in change buffer: ChangeBufferEntry(state=IN_PROGRESS, fschange=FSChange(Direction.UPLOAD, Action.CREATE, local_id=LocalID(inode=1407374883618530L, volume='serial:3188545052'), path=u'\\\\?\\C:\\workspace\\\ub179\ud654\\cakd3\\.git\\objects\\d7', name=u'e7903d08731a61fc9b560177c33a67c99b1d4c', parent_local_id=LocalID(inode=844424930197216L, volume='serial:3188545052'), is_folder=False, modified=1625291357, size=23159, generator_module=Generator.LOCAL_EVENT_GENERATOR, shared=False, row_id=2093), time=190560.593, row_id=1906)->ChangeBufferEntry(state=BLACKLISTED, fschange=FSChange(Direction.UPLOAD, Action.CREATE, local_id=LocalID(inode=1407374883618530L, volume='serial:3188545052'), path=u'\\\\?\\C:\\workspace\\\ub179\ud654\\cakd3\\.git\\objects\\d7', name=u'e7903d08731a61fc9b560177c33a67c99b1d4c', parent_local_id=LocalID(inode=844424930197216L, volume='serial:3188545052'), is_folder=False, modified=1625291357, size=23159, generator_module=Generator.LOCAL_EVENT_GENERATOR, shared=False, row_id=2093), blacklist_info=BlacklistInfoSub(key=u'\\\\?\\C:\\workspace\\\ub179\ud654\\cakd3\\.git\\objects\\d7\\e7903d08731a61fc9b560177c33a67c99b1d4c', fullname=u'\\\\?\\C:\\workspace\\\ub179\ud654\\cakd3\\.git\\objects\\d7\\e7903d08731a61fc9b560177c33a67c99b1d4c', direction=<Direction.UPLOAD: 'UPLOAD'>, failure=ClientDetectedCloudStorageQuotaExceeded(), entry_time=190690.859, url=None, is_folder=False, action=<Action.CREATE: 'CREATE'>), time=190560.593, row_id=1906)
2021-07-21 18:38:37,915 +0900 INFO pid=12760 12460:Worker-2        workers.py:192 Worker starting on [FSChange(Direction.UPLOAD, Action.CREATE, local_id=LocalID(inode=844424930197209L, volume='serial:3188545052'), path=u'\\\\?\\C:\\workspace\\\ub179\ud654\\cakd3\\.git\\objects\\d4', name=u'2fc0fc3424df32a7135c0542ff3414b612a1ad', parent_local_id=LocalID(inode=1407374883618520L, volume='serial:3188545052'), is_folder=False, modified=1625291484, size=4388, generator_module=Generator.LOCAL_EVENT_GENERATOR, shared=False, hash=1060827806, row_id=2095)]
2021-07-21 18:38:37,917 +0900 INFO pid=12760 12460:Worker-2        doc_id_provider.py:126 Returning doc ID '1UeJ2xQQUFWgwYwnFRo_fvXyD85e6c85S'. 2864 IDs left in store.
2021-07-21 18:38:37,918 +0900 INFO pid=12760 12460:Worker-2        snapshot_sqlite.py:647 Adding pre_mapping local_id=LocalID(inode=844424930197209L, volume='serial:3188545052'), doc_id=1UeJ2xQQUFWgwYwnFRo_fvXyD85e6c85S
2021-07-21 18:38:37,921 +0900 ERROR pid=12760 12460:Worker-2        workers.py:234 Exception while processing change [FSChange(Direction.UPLOAD, Action.CREATE, local_id=LocalID(inode=844424930197209L, volume='serial:3188545052'), path=u'\\\\?\\C:\\workspace\\\ub179\ud654\\cakd3\\.git\\objects\\d4', name=u'2fc0fc3424df32a7135c0542ff3414b612a1ad', parent_local_id=LocalID(inode=1407374883618520L, volume='serial:3188545052'), is_folder=False, modified=1625291484, size=4388, generator_module=Generator.LOCAL_EVENT_GENERATOR, shared=False, hash=1060827806, row_id=2095)]
Traceback (most recent call last):
  File "common\workers.py", line 201, in Process
  File "common\persistence\sqlite.py", line 141, in Wrapper
  File "common\workers.py", line 359, in _ProcessChanges
  File "common\worker\uploads.py", line 958, in Execute
  File "common\worker\uploads.py", line 1108, in _UploadCreate
  File "common\worker\workers_helper.py", line 406, in CreateCloudFile
  File "common\worker\workers_helper.py", line 372, in EnforceRemainingQuota
ClientDetectedCloudStorageQuotaExceeded: ClientDetectedCloudStorageQuotaExceeded: 'File size (4388) exceeds available space (-43553) on server.', recovery targets: set([])
2021-07-21 18:38:37,921 +0900 WARNING pid=12760 12460:Worker-2        workers.py:422 Setting recovery_targets for all changes. ClientDetectedCloudStorageQuotaExceeded: 'File size (4388) exceeds available space (-43553) on server.', recovery targets: set([])
2021-07-21 18:38:37,923 +0900 ERROR pid=12760 12460:Worker-2        fatal_exceptions.py:69 Ignoring non-fatal error: ClientDetectedCloudStorageQuotaExceeded: ClientDetectedCloudStorageQuotaExceeded: 'File size (4388) exceeds available space (-43553) on server.', recovery targets: set([LocalID(inode=1407374883618520L, volume='serial:3188545052'), LocalID(inode=844424930197209L, volume='serial:3188545052')]), Traceback:
  File "common\workers.py", line 201, in Process
  File "common\persistence\sqlite.py", line 141, in Wrapper
  File "common\workers.py", line 359, in _ProcessChanges
  File "common\worker\uploads.py", line 958, in Execute
  File "common\worker\uploads.py", line 1108, in _UploadCreate
  File "common\worker\workers_helper.py", line 406, in CreateCloudFile
  File "common\worker\workers_helper.py", line 372, in EnforceRemainingQuota

2021-07-21 18:38:37,940 +0900 INFO pid=12760 12468:Worker-1        workers.py:192 Worker starting on [FSChange(Direction.UPLOAD, Action.CREATE, local_id=LocalID(inode=844424930197210L, volume='serial:3188545052'), path=u'\\\\?\\C:\\workspace\\\ub179\ud654\\cakd3\\.git\\objects\\d4', name=u'3127f94052145cbfc9207f021fc786c13c0a63', parent_local_id=LocalID(inode=1407374883618520L, volume='serial:3188545052'), is_folder=False, modified=1625291481, size=182254, generator_module=Generator.LOCAL_EVENT_GENERATOR, shared=False, hash=1993056755, row_id=2096)]
2021-07-21 18:38:37,941 +0900 INFO pid=12760 12468:Worker-1        doc_id_provider.py:126 Returning doc ID '1RtO8zSCtmDdEBugHgukXf5Q7msbS8GbJ'. 2863 IDs left in store.
2021-07-21 18:38:37,941 +0900 INFO pid=12760 12468:Worker-1        snapshot_sqlite.py:647 Adding pre_mapping local_id=LocalID(inode=844424930197210L, volume='serial:3188545052'), doc_id=1RtO8zSCtmDdEBugHgukXf5Q7msbS8GbJ
2021-07-21 18:38:37,944 +0900 ERROR pid=12760 12468:Worker-1        workers.py:234 Exception while processing change [FSChange(Direction.UPLOAD, Action.CREATE, local_id=LocalID(inode=844424930197210L, volume='serial:3188545052'), path=u'\\\\?\\C:\\workspace\\\ub179\ud654\\cakd3\\.git\\objects\\d4', name=u'3127f94052145cbfc9207f021fc786c13c0a63', parent_local_id=LocalID(inode=1407374883618520L, volume='serial:3188545052'), is_folder=False, modified=1625291481, size=182254, generator_module=Generator.LOCAL_EVENT_GENERATOR, shared=False, hash=1993056755, row_id=2096)]
Traceback (most recent call last):
  File "common\workers.py", line 201, in Process
  File "common\persistence\sqlite.py", line 141, in Wrapper
  File "common\workers.py", line 359, in _ProcessChanges
  File "common\worker\uploads.py", line 958, in Execute
  File "common\worker\uploads.py", line 1108, in _UploadCreate
  File "common\worker\workers_helper.py", line 406, in CreateCloudFile
  File "common\worker\workers_helper.py", line 372, in EnforceRemainingQuota
ClientDetectedCloudStorageQuotaExceeded: ClientDetectedCloudStorageQuotaExceeded: 'File size (182254) exceeds available space (-43553) on server.', recovery targets: set([])
2021-07-21 18:38:37,944 +0900 WARNING pid=12760 12468:Worker-1        workers.py:422 Setting recovery_targets for all changes. ClientDetectedCloudStorageQuotaExceeded: 'File size (182254) exceeds available space (-43553) on server.', recovery targets: set([])
2021-07-21 18:38:37,946 +0900 ERROR pid=12760 12468:Worker-1        fatal_exceptions.py:69 Ignoring non-fatal error: ClientDetectedCloudStorageQuotaExceeded: ClientDetectedCloudStorageQuotaExceeded: 'File size (182254) exceeds available space (-43553) on server.', recovery targets: set([LocalID(inode=1407374883618520L, volume='serial:3188545052'), LocalID(inode=844424930197210L, volume='serial:3188545052')]), Traceback:
  File "common\workers.py", line 201, in Process
  File "common\persistence\sqlite.py", line 141, in Wrapper
  File "common\workers.py", line 359, in _ProcessChanges
  File "common\worker\uploads.py", line 958, in Execute
  File "common\worker\uploads.py", line 1108, in _UploadCreate
  File "common\worker\workers_helper.py", line 406, in CreateCloudFile
  File "common\worker\workers_helper.py", line 372, in EnforceRemainingQuota

2021-07-21 18:38:37,950 +0900 ERROR pid=12760 12460:Worker-2        blacklist.py:286 The following request has been blacklisted FSChange(Direction.UPLOAD, Action.CREATE, local_id=LocalID(inode=844424930197209L, volume='serial:3188545052'), path=u'\\\\?\\C:\\workspace\\\ub179\ud654\\cakd3\\.git\\objects\\d4', name=u'2fc0fc3424df32a7135c0542ff3414b612a1ad', parent_local_id=LocalID(inode=1407374883618520L, volume='serial:3188545052'), is_folder=False, modified=1625291484, size=4388, generator_module=Generator.LOCAL_EVENT_GENERATOR, shared=False, hash=1060827806, row_id=2095) Because of exception: ClientDetectedCloudStorageQuotaExceeded: 'File size (4388) exceeds available space (-43553) on server.', recovery targets: set([LocalID(inode=1407374883618520L, volume='serial:3188545052'), LocalID(inode=844424930197209L, volume='serial:3188545052')])
2021-07-21 18:38:37,950 +0900 INFO pid=12760 12460:Worker-2        change_buffer_entry.py:215 Replacing entry in change buffer: ChangeBufferEntry(state=IN_PROGRESS, fschange=FSChange(Direction.UPLOAD, Action.CREATE, local_id=LocalID(inode=844424930197209L, volume='serial:3188545052'), path=u'\\\\?\\C:\\workspace\\\ub179\ud654\\cakd3\\.git\\objects\\d4', name=u'2fc0fc3424df32a7135c0542ff3414b612a1ad', parent_local_id=LocalID(inode=1407374883618520L, volume='serial:3188545052'), is_folder=False, modified=1625291484, size=4388, generator_module=Generator.LOCAL_EVENT_GENERATOR, shared=False, row_id=2095), time=190560.765, row_id=1908)->ChangeBufferEntry(state=BLACKLISTED, fschange=FSChange(Direction.UPLOAD, Action.CREATE, local_id=LocalID(inode=844424930197209L, volume='serial:3188545052'), path=u'\\\\?\\C:\\workspace\\\ub179\ud654\\cakd3\\.git\\objects\\d4', name=u'2fc0fc3424df32a7135c0542ff3414b612a1ad', parent_local_id=LocalID(inode=1407374883618520L, volume='serial:3188545052'), is_folder=False, modified=1625291484, size=4388, generator_module=Generator.LOCAL_EVENT_GENERATOR, shared=False, row_id=2095), blacklist_info=BlacklistInfoSub(key=u'\\\\?\\C:\\workspace\\\ub179\ud654\\cakd3\\.git\\objects\\d4\\2fc0fc3424df32a7135c0542ff3414b612a1ad', fullname=u'\\\\?\\C:\\workspace\\\ub179\ud654\\cakd3\\.git\\objects\\d4\\2fc0fc3424df32a7135c0542ff3414b612a1ad', direction=<Direction.UPLOAD: 'UPLOAD'>, failure=ClientDetectedCloudStorageQuotaExceeded(), entry_time=190690.953, url=None, is_folder=False, action=<Action.CREATE: 'CREATE'>), time=190560.765, row_id=1908)
2021-07-21 18:38:37,992 +0900 ERROR pid=12760 12468:Worker-1        blacklist.py:286 The following request has been blacklisted FSChange(Direction.UPLOAD, Action.CREATE, local_id=LocalID(inode=844424930197210L, volume='serial:3188545052'), path=u'\\\\?\\C:\\workspace\\\ub179\ud654\\cakd3\\.git\\objects\\d4', name=u'3127f94052145cbfc9207f021fc786c13c0a63', parent_local_id=LocalID(inode=1407374883618520L, volume='serial:3188545052'), is_folder=False, modified=1625291481, size=182254, generator_module=Generator.LOCAL_EVENT_GENERATOR, shared=False, hash=1993056755, row_id=2096) Because of exception: ClientDetectedCloudStorageQuotaExceeded: 'File size (182254) exceeds available space (-43553) on server.', recovery targets: set([LocalID(inode=1407374883618520L, volume='serial:3188545052'), LocalID(inode=844424930197210L, volume='serial:3188545052')])
2021-07-21 18:38:37,993 +0900 INFO pid=12760 12468:Worker-1        change_buffer_entry.py:215 Replacing entry in change buffer: ChangeBufferEntry(state=IN_PROGRESS, fschange=FSChange(Direction.UPLOAD, Action.CREATE, local_id=LocalID(inode=844424930197210L, volume='serial:3188545052'), path=u'\\\\?\\C:\\workspace\\\ub179\ud654\\cakd3\\.git\\objects\\d4', name=u'3127f94052145cbfc9207f021fc786c13c0a63', parent_local_id=LocalID(inode=1407374883618520L, volume='serial:3188545052'), is_folder=False, modified=1625291481, size=182254, generator_module=Generator.LOCAL_EVENT_GENERATOR, shared=False, row_id=2096), time=190560.796, row_id=1909)->ChangeBufferEntry(state=BLACKLISTED, fschange=FSChange(Direction.UPLOAD, Action.CREATE, local_id=LocalID(inode=844424930197210L, volume='serial:3188545052'), path=u'\\\\?\\C:\\workspace\\\ub179\ud654\\cakd3\\.git\\objects\\d4', name=u'3127f94052145cbfc9207f021fc786c13c0a63', parent_local_id=LocalID(inode=1407374883618520L, volume='serial:3188545052'), is_folder=False, modified=1625291481, size=182254, generator_module=Generator.LOCAL_EVENT_GENERATOR, shared=False, row_id=2096), blacklist_info=BlacklistInfoSub(key=u'\\\\?\\C:\\workspace\\\ub179\ud654\\cakd3\\.git\\objects\\d4\\3127f94052145cbfc9207f021fc786c13c0a63', fullname=u'\\\\?\\C:\\workspace\\\ub179\ud654\\cakd3\\.git\\objects\\d4\\3127f94052145cbfc9207f021fc786c13c0a63', direction=<Direction.UPLOAD: 'UPLOAD'>, failure=ClientDetectedCloudStorageQuotaExceeded(), entry_time=190690.984, url=None, is_folder=False, action=<Action.CREATE: 'CREATE'>), time=190560.796, row_id=1909)
2021-07-21 18:38:38,051 +0900 INFO pid=12760 10252:Worker-0        workers.py:192 Worker starting on [FSChange(Direction.UPLOAD, Action.CREATE, local_id=LocalID(inode=844424930197212L, volume='serial:3188545052'), path=u'\\\\?\\C:\\workspace\\\ub179\ud654\\cakd3\\.git\\objects\\d5', name=u'598afa1e9e77b00e659db59113cea84dfcfd3c', parent_local_id=LocalID(inode=844424930197211L, volume='serial:3188545052'), is_folder=False, modified=1625291357, size=555, generator_module=Generator.LOCAL_EVENT_GENERATOR, shared=False, hash=570756172, row_id=2098)]
2021-07-21 18:38:38,052 +0900 INFO pid=12760 10252:Worker-0        doc_id_provider.py:126 Returning doc ID '11QD5XETnBmD7cCBDAHshxID62o_HoLLl'. 2862 IDs left in store.
2021-07-21 18:38:38,053 +0900 INFO pid=12760 10252:Worker-0        snapshot_sqlite.py:647 Adding pre_mapping local_id=LocalID(inode=844424930197212L, volume='serial:3188545052'), doc_id=11QD5XETnBmD7cCBDAHshxID62o_HoLLl
2021-07-21 18:38:38,056 +0900 ERROR pid=12760 10252:Worker-0        workers.py:234 Exception while processing change [FSChange(Direction.UPLOAD, Action.CREATE, local_id=LocalID(inode=844424930197212L, volume='serial:3188545052'), path=u'\\\\?\\C:\\workspace\\\ub179\ud654\\cakd3\\.git\\objects\\d5', name=u'598afa1e9e77b00e659db59113cea84dfcfd3c', parent_local_id=LocalID(inode=844424930197211L, volume='serial:3188545052'), is_folder=False, modified=1625291357, size=555, generator_module=Generator.LOCAL_EVENT_GENERATOR, shared=False, hash=570756172, row_id=2098)]
Traceback (most recent call last):
  File "common\workers.py", line 201, in Process
  File "common\persistence\sqlite.py", line 141, in Wrapper
  File "common\workers.py", line 359, in _ProcessChanges
  File "common\worker\uploads.py", line 958, in Execute
  File "common\worker\uploads.py", line 1108, in _UploadCreate
  File "common\worker\workers_helper.py", line 406, in CreateCloudFile
  File "common\worker\workers_helper.py", line 372, in EnforceRemainingQuota
ClientDetectedCloudStorageQuotaExceeded: ClientDetectedCloudStorageQuotaExceeded: 'File size (555) exceeds available space (-43553) on server.', recovery targets: set([])
2021-07-21 18:38:38,058 +0900 WARNING pid=12760 10252:Worker-0        workers.py:422 Setting recovery_targets for all changes. ClientDetectedCloudStorageQuotaExceeded: 'File size (555) exceeds available space (-43553) on server.', recovery targets: set([])
2021-07-21 18:38:38,059 +0900 ERROR pid=12760 10252:Worker-0        fatal_exceptions.py:69 Ignoring non-fatal error: ClientDetectedCloudStorageQuotaExceeded: ClientDetectedCloudStorageQuotaExceeded: 'File size (555) exceeds available space (-43553) on server.', recovery targets: set([LocalID(inode=844424930197212L, volume='serial:3188545052'), LocalID(inode=844424930197211L, volume='serial:3188545052')]), Traceback:
  File "common\workers.py", line 201, in Process
  File "common\persistence\sqlite.py", line 141, in Wrapper
  File "common\workers.py", line 359, in _ProcessChanges
  File "common\worker\uploads.py", line 958, in Execute
  File "common\worker\uploads.py", line 1108, in _UploadCreate
  File "common\worker\workers_helper.py", line 406, in CreateCloudFile
  File "common\worker\workers_helper.py", line 372, in EnforceRemainingQuota

2021-07-21 18:38:38,069 +0900 ERROR pid=12760 10252:Worker-0        blacklist.py:286 The following request has been blacklisted FSChange(Direction.UPLOAD, Action.CREATE, local_id=LocalID(inode=844424930197212L, volume='serial:3188545052'), path=u'\\\\?\\C:\\workspace\\\ub179\ud654\\cakd3\\.git\\objects\\d5', name=u'598afa1e9e77b00e659db59113cea84dfcfd3c', parent_local_id=LocalID(inode=844424930197211L, volume='serial:3188545052'), is_folder=False, modified=1625291357, size=555, generator_module=Generator.LOCAL_EVENT_GENERATOR, shared=False, hash=570756172, row_id=2098) Because of exception: ClientDetectedCloudStorageQuotaExceeded: 'File size (555) exceeds available space (-43553) on server.', recovery targets: set([LocalID(inode=844424930197212L, volume='serial:3188545052'), LocalID(inode=844424930197211L, volume='serial:3188545052')])
2021-07-21 18:38:38,069 +0900 INFO pid=12760 10252:Worker-0        change_buffer_entry.py:215 Replacing entry in change buffer: ChangeBufferEntry(state=IN_PROGRESS, fschange=FSChange(Direction.UPLOAD, Action.CREATE, local_id=LocalID(inode=844424930197212L, volume='serial:3188545052'), path=u'\\\\?\\C:\\workspace\\\ub179\ud654\\cakd3\\.git\\objects\\d5', name=u'598afa1e9e77b00e659db59113cea84dfcfd3c', parent_local_id=LocalID(inode=844424930197211L, volume='serial:3188545052'), is_folder=False, modified=1625291357, size=555, generator_module=Generator.LOCAL_EVENT_GENERATOR, shared=False, row_id=2098), time=190561, row_id=1911)->ChangeBufferEntry(state=BLACKLISTED, fschange=FSChange(Direction.UPLOAD, Action.CREATE, local_id=LocalID(inode=844424930197212L, volume='serial:3188545052'), path=u'\\\\?\\C:\\workspace\\\ub179\ud654\\cakd3\\.git\\objects\\d5', name=u'598afa1e9e77b00e659db59113cea84dfcfd3c', parent_local_id=LocalID(inode=844424930197211L, volume='serial:3188545052'), is_folder=False, modified=1625291357, size=555, generator_module=Generator.LOCAL_EVENT_GENERATOR, shared=False, row_id=2098), blacklist_info=BlacklistInfoSub(key=u'\\\\?\\C:\\workspace\\\ub179\ud654\\cakd3\\.git\\objects\\d5\\598afa1e9e77b00e659db59113cea84dfcfd3c', fullname=u'\\\\?\\C:\\workspace\\\ub179\ud654\\cakd3\\.git\\objects\\d5\\598afa1e9e77b00e659db59113cea84dfcfd3c', direction=<Direction.UPLOAD: 'UPLOAD'>, failure=ClientDetectedCloudStorageQuotaExceeded(), entry_time=190691.062, url=None, is_folder=False, action=<Action.CREATE: 'CREATE'>), time=190561, row_id=1911)
2021-07-21 18:38:38,130 +0900 INFO pid=12760 12460:Worker-2        workers.py:192 Worker starting on [FSChange(Direction.UPLOAD, Action.CREATE, local_id=LocalID(inode=844424930197213L, volume='serial:3188545052'), path=u'\\\\?\\C:\\workspace\\\ub179\ud654\\cakd3\\.git\\objects\\d5', name=u'90c0913e6b23016b69d05435647b18a2092a8a', parent_local_id=LocalID(inode=844424930197211L, volume='serial:3188545052'), is_folder=False, modified=1625291484, size=53752, generator_module=Generator.LOCAL_EVENT_GENERATOR, shared=False, hash=-1313491221, row_id=2099)]
2021-07-21 18:38:38,131 +0900 INFO pid=12760 12460:Worker-2        doc_id_provider.py:126 Returning doc ID '1xxb3RARO2S6OOPmF-DMWSE5UbvzxXriz'. 2861 IDs left in store.
2021-07-21 18:38:38,132 +0900 INFO pid=12760 12460:Worker-2        snapshot_sqlite.py:647 Adding pre_mapping local_id=LocalID(inode=844424930197213L, volume='serial:3188545052'), doc_id=1xxb3RARO2S6OOPmF-DMWSE5UbvzxXriz
2021-07-21 18:38:38,134 +0900 ERROR pid=12760 12460:Worker-2        workers.py:234 Exception while processing change [FSChange(Direction.UPLOAD, Action.CREATE, local_id=LocalID(inode=844424930197213L, volume='serial:3188545052'), path=u'\\\\?\\C:\\workspace\\\ub179\ud654\\cakd3\\.git\\objects\\d5', name=u'90c0913e6b23016b69d05435647b18a2092a8a', parent_local_id=LocalID(inode=844424930197211L, volume='serial:3188545052'), is_folder=False, modified=1625291484, size=53752, generator_module=Generator.LOCAL_EVENT_GENERATOR, shared=False, hash=-1313491221, row_id=2099)]
Traceback (most recent call last):
  File "common\workers.py", line 201, in Process
  File "common\persistence\sqlite.py", line 141, in Wrapper
  File "common\workers.py", line 359, in _ProcessChanges
  File "common\worker\uploads.py", line 958, in Execute
  File "common\worker\uploads.py", line 1108, in _UploadCreate
  File "common\worker\workers_helper.py", line 406, in CreateCloudFile
  File "common\worker\workers_helper.py", line 372, in EnforceRemainingQuota
ClientDetectedCloudStorageQuotaExceeded: ClientDetectedCloudStorageQuotaExceeded: 'File size (53752) exceeds available space (-43553) on server.', recovery targets: set([])
2021-07-21 18:38:38,134 +0900 WARNING pid=12760 12460:Worker-2        workers.py:422 Setting recovery_targets for all changes. ClientDetectedCloudStorageQuotaExceeded: 'File size (53752) exceeds available space (-43553) on server.', recovery targets: set([])
2021-07-21 18:38:38,134 +0900 ERROR pid=12760 12460:Worker-2        fatal_exceptions.py:69 Ignoring non-fatal error: ClientDetectedCloudStorageQuotaExceeded: ClientDetectedCloudStorageQuotaExceeded: 'File size (53752) exceeds available space (-43553) on server.', recovery targets: set([LocalID(inode=844424930197213L, volume='serial:3188545052'), LocalID(inode=844424930197211L, volume='serial:3188545052')]), Traceback:
  File "common\workers.py", line 201, in Process
  File "common\persistence\sqlite.py", line 141, in Wrapper
  File "common\workers.py", line 359, in _ProcessChanges
  File "common\worker\uploads.py", line 958, in Execute
  File "common\worker\uploads.py", line 1108, in _UploadCreate
  File "common\worker\workers_helper.py", line 406, in CreateCloudFile
  File "common\worker\workers_helper.py", line 372, in EnforceRemainingQuota

2021-07-21 18:38:38,157 +0900 INFO pid=12760 12468:Worker-1        workers.py:192 Worker starting on [FSChange(Direction.UPLOAD, Action.CREATE, local_id=LocalID(inode=844424930197273L, volume='serial:3188545052'), path=u'\\\\?\\C:\\workspace\\\ub179\ud654\\cakd3\\.git\\objects\\eb', name=u'5eec69ead52466a65b699fe81097d61f3e38c7', parent_local_id=LocalID(inode=844424930197272L, volume='serial:3188545052'), is_folder=False, modified=1625291484, size=52803, generator_module=Generator.LOCAL_EVENT_GENERATOR, shared=False, hash=1137495331, row_id=2101)]
2021-07-21 18:38:38,160 +0900 INFO pid=12760 12468:Worker-1        doc_id_provider.py:126 Returning doc ID '18SHmUxhDWsjmalsy4C9eEZMpmI7HdPk0'. 2860 IDs left in store.
2021-07-21 18:38:38,161 +0900 INFO pid=12760 12468:Worker-1        snapshot_sqlite.py:647 Adding pre_mapping local_id=LocalID(inode=844424930197273L, volume='serial:3188545052'), doc_id=18SHmUxhDWsjmalsy4C9eEZMpmI7HdPk0
2021-07-21 18:38:38,163 +0900 ERROR pid=12760 12468:Worker-1        workers.py:234 Exception while processing change [FSChange(Direction.UPLOAD, Action.CREATE, local_id=LocalID(inode=844424930197273L, volume='serial:3188545052'), path=u'\\\\?\\C:\\workspace\\\ub179\ud654\\cakd3\\.git\\objects\\eb', name=u'5eec69ead52466a65b699fe81097d61f3e38c7', parent_local_id=LocalID(inode=844424930197272L, volume='serial:3188545052'), is_folder=False, modified=1625291484, size=52803, generator_module=Generator.LOCAL_EVENT_GENERATOR, shared=False, hash=1137495331, row_id=2101)]
Traceback (most recent call last):
  File "common\workers.py", line 201, in Process
  File "common\persistence\sqlite.py", line 141, in Wrapper
  File "common\workers.py", line 359, in _ProcessChanges
  File "common\worker\uploads.py", line 958, in Execute
  File "common\worker\uploads.py", line 1108, in _UploadCreate
  File "common\worker\workers_helper.py", line 406, in CreateCloudFile
  File "common\worker\workers_helper.py", line 372, in EnforceRemainingQuota
ClientDetectedCloudStorageQuotaExceeded: ClientDetectedCloudStorageQuotaExceeded: 'File size (52803) exceeds available space (-43553) on server.', recovery targets: set([])
2021-07-21 18:38:38,164 +0900 WARNING pid=12760 12468:Worker-1        workers.py:422 Setting recovery_targets for all changes. ClientDetectedCloudStorageQuotaExceeded: 'File size (52803) exceeds available space (-43553) on server.', recovery targets: set([])
2021-07-21 18:38:38,164 +0900 ERROR pid=12760 12468:Worker-1        fatal_exceptions.py:69 Ignoring non-fatal error: ClientDetectedCloudStorageQuotaExceeded: ClientDetectedCloudStorageQuotaExceeded: 'File size (52803) exceeds available space (-43553) on server.', recovery targets: set([LocalID(inode=844424930197272L, volume='serial:3188545052'), LocalID(inode=844424930197273L, volume='serial:3188545052')]), Traceback:
  File "common\workers.py", line 201, in Process
  File "common\persistence\sqlite.py", line 141, in Wrapper
  File "common\workers.py", line 359, in _ProcessChanges
  File "common\worker\uploads.py", line 958, in Execute
  File "common\worker\uploads.py", line 1108, in _UploadCreate
  File "common\worker\workers_helper.py", line 406, in CreateCloudFile
  File "common\worker\workers_helper.py", line 372, in EnforceRemainingQuota

2021-07-21 18:38:38,167 +0900 ERROR pid=12760 12460:Worker-2        blacklist.py:286 The following request has been blacklisted FSChange(Direction.UPLOAD, Action.CREATE, local_id=LocalID(inode=844424930197213L, volume='serial:3188545052'), path=u'\\\\?\\C:\\workspace\\\ub179\ud654\\cakd3\\.git\\objects\\d5', name=u'90c0913e6b23016b69d05435647b18a2092a8a', parent_local_id=LocalID(inode=844424930197211L, volume='serial:3188545052'), is_folder=False, modified=1625291484, size=53752, generator_module=Generator.LOCAL_EVENT_GENERATOR, shared=False, hash=-1313491221, row_id=2099) Because of exception: ClientDetectedCloudStorageQuotaExceeded: 'File size (53752) exceeds available space (-43553) on server.', recovery targets: set([LocalID(inode=844424930197213L, volume='serial:3188545052'), LocalID(inode=844424930197211L, volume='serial:3188545052')])
2021-07-21 18:38:38,167 +0900 INFO pid=12760 12460:Worker-2        change_buffer_entry.py:215 Replacing entry in change buffer: ChangeBufferEntry(state=IN_PROGRESS, fschange=FSChange(Direction.UPLOAD, Action.CREATE, local_id=LocalID(inode=844424930197213L, volume='serial:3188545052'), path=u'\\\\?\\C:\\workspace\\\ub179\ud654\\cakd3\\.git\\objects\\d5', name=u'90c0913e6b23016b69d05435647b18a2092a8a', parent_local_id=LocalID(inode=844424930197211L, volume='serial:3188545052'), is_folder=False, modified=1625291484, size=53752, generator_module=Generator.LOCAL_EVENT_GENERATOR, shared=False, row_id=2099), time=190561.031, row_id=1912)->ChangeBufferEntry(state=BLACKLISTED, fschange=FSChange(Direction.UPLOAD, Action.CREATE, local_id=LocalID(inode=844424930197213L, volume='serial:3188545052'), path=u'\\\\?\\C:\\workspace\\\ub179\ud654\\cakd3\\.git\\objects\\d5', name=u'90c0913e6b23016b69d05435647b18a2092a8a', parent_local_id=LocalID(inode=844424930197211L, volume='serial:3188545052'), is_folder=False, modified=1625291484, size=53752, generator_module=Generator.LOCAL_EVENT_GENERATOR, shared=False, row_id=2099), blacklist_info=BlacklistInfoSub(key=u'\\\\?\\C:\\workspace\\\ub179\ud654\\cakd3\\.git\\objects\\d5\\90c0913e6b23016b69d05435647b18a2092a8a', fullname=u'\\\\?\\C:\\workspace\\\ub179\ud654\\cakd3\\.git\\objects\\d5\\90c0913e6b23016b69d05435647b18a2092a8a', direction=<Direction.UPLOAD: 'UPLOAD'>, failure=ClientDetectedCloudStorageQuotaExceeded(), entry_time=190691.171, url=None, is_folder=False, action=<Action.CREATE: 'CREATE'>), time=190561.031, row_id=1912)
2021-07-21 18:38:38,213 +0900 ERROR pid=12760 12468:Worker-1        blacklist.py:286 The following request has been blacklisted FSChange(Direction.UPLOAD, Action.CREATE, local_id=LocalID(inode=844424930197273L, volume='serial:3188545052'), path=u'\\\\?\\C:\\workspace\\\ub179\ud654\\cakd3\\.git\\objects\\eb', name=u'5eec69ead52466a65b699fe81097d61f3e38c7', parent_local_id=LocalID(inode=844424930197272L, volume='serial:3188545052'), is_folder=False, modified=1625291484, size=52803, generator_module=Generator.LOCAL_EVENT_GENERATOR, shared=False, hash=1137495331, row_id=2101) Because of exception: ClientDetectedCloudStorageQuotaExceeded: 'File size (52803) exceeds available space (-43553) on server.', recovery targets: set([LocalID(inode=844424930197272L, volume='serial:3188545052'), LocalID(inode=844424930197273L, volume='serial:3188545052')])
2021-07-21 18:38:38,214 +0900 INFO pid=12760 12468:Worker-1        change_buffer_entry.py:215 Replacing entry in change buffer: ChangeBufferEntry(state=IN_PROGRESS, fschange=FSChange(Direction.UPLOAD, Action.CREATE, local_id=LocalID(inode=844424930197273L, volume='serial:3188545052'), path=u'\\\\?\\C:\\workspace\\\ub179\ud654\\cakd3\\.git\\objects\\eb', name=u'5eec69ead52466a65b699fe81097d61f3e38c7', parent_local_id=LocalID(inode=844424930197272L, volume='serial:3188545052'), is_folder=False, modified=1625291484, size=52803, generator_module=Generator.LOCAL_EVENT_GENERATOR, shared=False, row_id=2101), time=190561.359, row_id=1914)->ChangeBufferEntry(state=BLACKLISTED, fschange=FSChange(Direction.UPLOAD, Action.CREATE, local_id=LocalID(inode=844424930197273L, volume='serial:3188545052'), path=u'\\\\?\\C:\\workspace\\\ub179\ud654\\cakd3\\.git\\objects\\eb', name=u'5eec69ead52466a65b699fe81097d61f3e38c7', parent_local_id=LocalID(inode=844424930197272L, volume='serial:3188545052'), is_folder=False, modified=1625291484, size=52803, generator_module=Generator.LOCAL_EVENT_GENERATOR, shared=False, row_id=2101), blacklist_info=BlacklistInfoSub(key=u'\\\\?\\C:\\workspace\\\ub179\ud654\\cakd3\\.git\\objects\\eb\\5eec69ead52466a65b699fe81097d61f3e38c7', fullname=u'\\\\?\\C:\\workspace\\\ub179\ud654\\cakd3\\.git\\objects\\eb\\5eec69ead52466a65b699fe81097d61f3e38c7', direction=<Direction.UPLOAD: 'UPLOAD'>, failure=ClientDetectedCloudStorageQuotaExceeded(), entry_time=190691.218, url=None, is_folder=False, action=<Action.CREATE: 'CREATE'>), time=190561.359, row_id=1914)
2021-07-21 18:38:38,276 +0900 INFO pid=12760 10252:Worker-0        workers.py:192 Worker starting on [FSChange(Direction.UPLOAD, Action.CREATE, local_id=LocalID(inode=1970324837039898L, volume='serial:3188545052'), path=u'\\\\?\\C:\\workspace\\\ub179\ud654\\cakd3\\.git\\objects\\eb', name=u'9bde7c5ab7c4e18e296ade6e178ad8ed2e3110', parent_local_id=LocalID(inode=844424930197272L, volume='serial:3188545052'), is_folder=False, modified=1625291484, size=102896, generator_module=Generator.LOCAL_EVENT_GENERATOR, shared=False, hash=-2016099484, row_id=2102)]
2021-07-21 18:38:38,279 +0900 INFO pid=12760 10252:Worker-0        doc_id_provider.py:126 Returning doc ID '1emP7zRuvyNTz4PWOH4DS36tS3TP33oSk'. 2859 IDs left in store.
2021-07-21 18:38:38,279 +0900 INFO pid=12760 10252:Worker-0        snapshot_sqlite.py:647 Adding pre_mapping local_id=LocalID(inode=1970324837039898L, volume='serial:3188545052'), doc_id=1emP7zRuvyNTz4PWOH4DS36tS3TP33oSk
2021-07-21 18:38:38,280 +0900 ERROR pid=12760 10252:Worker-0        workers.py:234 Exception while processing change [FSChange(Direction.UPLOAD, Action.CREATE, local_id=LocalID(inode=1970324837039898L, volume='serial:3188545052'), path=u'\\\\?\\C:\\workspace\\\ub179\ud654\\cakd3\\.git\\objects\\eb', name=u'9bde7c5ab7c4e18e296ade6e178ad8ed2e3110', parent_local_id=LocalID(inode=844424930197272L, volume='serial:3188545052'), is_folder=False, modified=1625291484, size=102896, generator_module=Generator.LOCAL_EVENT_GENERATOR, shared=False, hash=-2016099484, row_id=2102)]
Traceback (most recent call last):
  File "common\workers.py", line 201, in Process
  File "common\persistence\sqlite.py", line 141, in Wrapper
  File "common\workers.py", line 359, in _ProcessChanges
  File "common\worker\uploads.py", line 958, in Execute
  File "common\worker\uploads.py", line 1108, in _UploadCreate
  File "common\worker\workers_helper.py", line 406, in CreateCloudFile
  File "common\worker\workers_helper.py", line 372, in EnforceRemainingQuota
ClientDetectedCloudStorageQuotaExceeded: ClientDetectedCloudStorageQuotaExceeded: 'File size (102896) exceeds available space (-43553) on server.', recovery targets: set([])
2021-07-21 18:38:38,282 +0900 WARNING pid=12760 10252:Worker-0        workers.py:422 Setting recovery_targets for all changes. ClientDetectedCloudStorageQuotaExceeded: 'File size (102896) exceeds available space (-43553) on server.', recovery targets: set([])
2021-07-21 18:38:38,282 +0900 ERROR pid=12760 10252:Worker-0        fatal_exceptions.py:69 Ignoring non-fatal error: ClientDetectedCloudStorageQuotaExceeded: ClientDetectedCloudStorageQuotaExceeded: 'File size (102896) exceeds available space (-43553) on server.', recovery targets: set([LocalID(inode=844424930197272L, volume='serial:3188545052'), LocalID(inode=1970324837039898L, volume='serial:3188545052')]), Traceback:
  File "common\workers.py", line 201, in Process
  File "common\persistence\sqlite.py", line 141, in Wrapper
  File "common\workers.py", line 359, in _ProcessChanges
  File "common\worker\uploads.py", line 958, in Execute
  File "common\worker\uploads.py", line 1108, in _UploadCreate
  File "common\worker\workers_helper.py", line 406, in CreateCloudFile
  File "common\worker\workers_helper.py", line 372, in EnforceRemainingQuota

2021-07-21 18:38:38,295 +0900 ERROR pid=12760 10252:Worker-0        blacklist.py:286 The following request has been blacklisted FSChange(Direction.UPLOAD, Action.CREATE, local_id=LocalID(inode=1970324837039898L, volume='serial:3188545052'), path=u'\\\\?\\C:\\workspace\\\ub179\ud654\\cakd3\\.git\\objects\\eb', name=u'9bde7c5ab7c4e18e296ade6e178ad8ed2e3110', parent_local_id=LocalID(inode=844424930197272L, volume='serial:3188545052'), is_folder=False, modified=1625291484, size=102896, generator_module=Generator.LOCAL_EVENT_GENERATOR, shared=False, hash=-2016099484, row_id=2102) Because of exception: ClientDetectedCloudStorageQuotaExceeded: 'File size (102896) exceeds available space (-43553) on server.', recovery targets: set([LocalID(inode=844424930197272L, volume='serial:3188545052'), LocalID(inode=1970324837039898L, volume='serial:3188545052')])
2021-07-21 18:38:38,295 +0900 INFO pid=12760 10252:Worker-0        change_buffer_entry.py:215 Replacing entry in change buffer: ChangeBufferEntry(state=IN_PROGRESS, fschange=FSChange(Direction.UPLOAD, Action.CREATE, local_id=LocalID(inode=1970324837039898L, volume='serial:3188545052'), path=u'\\\\?\\C:\\workspace\\\ub179\ud654\\cakd3\\.git\\objects\\eb', name=u'9bde7c5ab7c4e18e296ade6e178ad8ed2e3110', parent_local_id=LocalID(inode=844424930197272L, volume='serial:3188545052'), is_folder=False, modified=1625291484, size=102896, generator_module=Generator.LOCAL_EVENT_GENERATOR, shared=False, row_id=2102), time=190561.39, row_id=1915)->ChangeBufferEntry(state=BLACKLISTED, fschange=FSChange(Direction.UPLOAD, Action.CREATE, local_id=LocalID(inode=1970324837039898L, volume='serial:3188545052'), path=u'\\\\?\\C:\\workspace\\\ub179\ud654\\cakd3\\.git\\objects\\eb', name=u'9bde7c5ab7c4e18e296ade6e178ad8ed2e3110', parent_local_id=LocalID(inode=844424930197272L, volume='serial:3188545052'), is_folder=False, modified=1625291484, size=102896, generator_module=Generator.LOCAL_EVENT_GENERATOR, shared=False, row_id=2102), blacklist_info=BlacklistInfoSub(key=u'\\\\?\\C:\\workspace\\\ub179\ud654\\cakd3\\.git\\objects\\eb\\9bde7c5ab7c4e18e296ade6e178ad8ed2e3110', fullname=u'\\\\?\\C:\\workspace\\\ub179\ud654\\cakd3\\.git\\objects\\eb\\9bde7c5ab7c4e18e296ade6e178ad8ed2e3110', direction=<Direction.UPLOAD: 'UPLOAD'>, failure=ClientDetectedCloudStorageQuotaExceeded(), entry_time=190691.296, url=None, is_folder=False, action=<Action.CREATE: 'CREATE'>), time=190561.39, row_id=1915)
2021-07-21 18:38:38,355 +0900 INFO pid=12760 12460:Worker-2        workers.py:192 Worker starting on [FSChange(Direction.UPLOAD, Action.CREATE, local_id=LocalID(inode=1970324837039899L, volume='serial:3188545052'), path=u'\\\\?\\C:\\workspace\\\ub179\ud654\\cakd3\\.git\\objects\\eb', name=u'a37d954ce9f9dea455806a33dd557217012837', parent_local_id=LocalID(inode=844424930197272L, volume='serial:3188545052'), is_folder=False, modified=1625291357, size=436, generator_module=Generator.LOCAL_EVENT_GENERATOR, shared=False, hash=-130817987, row_id=2103)]
2021-07-21 18:38:38,358 +0900 INFO pid=12760 12460:Worker-2        doc_id_provider.py:126 Returning doc ID '1_tSYGHPfbJJoXsKsdpCnfWZ3IGDsLnju'. 2858 IDs left in store.
2021-07-21 18:38:38,358 +0900 INFO pid=12760 12460:Worker-2        snapshot_sqlite.py:647 Adding pre_mapping local_id=LocalID(inode=1970324837039899L, volume='serial:3188545052'), doc_id=1_tSYGHPfbJJoXsKsdpCnfWZ3IGDsLnju
2021-07-21 18:38:38,361 +0900 ERROR pid=12760 12460:Worker-2        workers.py:234 Exception while processing change [FSChange(Direction.UPLOAD, Action.CREATE, local_id=LocalID(inode=1970324837039899L, volume='serial:3188545052'), path=u'\\\\?\\C:\\workspace\\\ub179\ud654\\cakd3\\.git\\objects\\eb', name=u'a37d954ce9f9dea455806a33dd557217012837', parent_local_id=LocalID(inode=844424930197272L, volume='serial:3188545052'), is_folder=False, modified=1625291357, size=436, generator_module=Generator.LOCAL_EVENT_GENERATOR, shared=False, hash=-130817987, row_id=2103)]
Traceback (most recent call last):
  File "common\workers.py", line 201, in Process
  File "common\persistence\sqlite.py", line 141, in Wrapper
  File "common\workers.py", line 359, in _ProcessChanges
  File "common\worker\uploads.py", line 958, in Execute
  File "common\worker\uploads.py", line 1108, in _UploadCreate
  File "common\worker\workers_helper.py", line 406, in CreateCloudFile
  File "common\worker\workers_helper.py", line 372, in EnforceRemainingQuota
ClientDetectedCloudStorageQuotaExceeded: ClientDetectedCloudStorageQuotaExceeded: 'File size (436) exceeds available space (-43553) on server.', recovery targets: set([])
2021-07-21 18:38:38,361 +0900 WARNING pid=12760 12460:Worker-2        workers.py:422 Setting recovery_targets for all changes. ClientDetectedCloudStorageQuotaExceeded: 'File size (436) exceeds available space (-43553) on server.', recovery targets: set([])
2021-07-21 18:38:38,362 +0900 ERROR pid=12760 12460:Worker-2        fatal_exceptions.py:69 Ignoring non-fatal error: ClientDetectedCloudStorageQuotaExceeded: ClientDetectedCloudStorageQuotaExceeded: 'File size (436) exceeds available space (-43553) on server.', recovery targets: set([LocalID(inode=844424930197272L, volume='serial:3188545052'), LocalID(inode=1970324837039899L, volume='serial:3188545052')]), Traceback:
  File "common\workers.py", line 201, in Process
  File "common\persistence\sqlite.py", line 141, in Wrapper
  File "common\workers.py", line 359, in _ProcessChanges
  File "common\worker\uploads.py", line 958, in Execute
  File "common\worker\uploads.py", line 1108, in _UploadCreate
  File "common\worker\workers_helper.py", line 406, in CreateCloudFile
  File "common\worker\workers_helper.py", line 372, in EnforceRemainingQuota

2021-07-21 18:38:38,592 +0900 INFO pid=12760 12468:Worker-1        workers.py:192 Worker starting on [FSChange(Direction.UPLOAD, Action.CREATE, local_id=LocalID(inode=1125899906907862L, volume='serial:3188545052'), path=u'\\\\?\\C:\\workspace\\\ub179\ud654\\cakd3\\.git\\objects\\d3', name=u'd4368936657b570bf81b9bd87d02f29cfc1179', parent_local_id=LocalID(inode=1125899906907860L, volume='serial:3188545052'), is_folder=False, modified=1625291484, size=155484, generator_module=Generator.LOCAL_EVENT_GENERATOR, shared=False, hash=-9935624, row_id=2105)]
2021-07-21 18:38:38,595 +0900 INFO pid=12760 12468:Worker-1        doc_id_provider.py:126 Returning doc ID '1Ngci7ZFIR0xJLgN_WFjH91taSc72ylJa'. 2857 IDs left in store.
2021-07-21 18:38:38,595 +0900 INFO pid=12760 12468:Worker-1        snapshot_sqlite.py:647 Adding pre_mapping local_id=LocalID(inode=1125899906907862L, volume='serial:3188545052'), doc_id=1Ngci7ZFIR0xJLgN_WFjH91taSc72ylJa
2021-07-21 18:38:38,598 +0900 ERROR pid=12760 12468:Worker-1        workers.py:234 Exception while processing change [FSChange(Direction.UPLOAD, Action.CREATE, local_id=LocalID(inode=1125899906907862L, volume='serial:3188545052'), path=u'\\\\?\\C:\\workspace\\\ub179\ud654\\cakd3\\.git\\objects\\d3', name=u'd4368936657b570bf81b9bd87d02f29cfc1179', parent_local_id=LocalID(inode=1125899906907860L, volume='serial:3188545052'), is_folder=False, modified=1625291484, size=155484, generator_module=Generator.LOCAL_EVENT_GENERATOR, shared=False, hash=-9935624, row_id=2105)]
Traceback (most recent call last):
  File "common\workers.py", line 201, in Process
  File "common\persistence\sqlite.py", line 141, in Wrapper
  File "common\workers.py", line 359, in _ProcessChanges
  File "common\worker\uploads.py", line 958, in Execute
  File "common\worker\uploads.py", line 1108, in _UploadCreate
  File "common\worker\workers_helper.py", line 406, in CreateCloudFile
  File "common\worker\workers_helper.py", line 372, in EnforceRemainingQuota
ClientDetectedCloudStorageQuotaExceeded: ClientDetectedCloudStorageQuotaExceeded: 'File size (155484) exceeds available space (-43553) on server.', recovery targets: set([])
2021-07-21 18:38:38,598 +0900 WARNING pid=12760 12468:Worker-1        workers.py:422 Setting recovery_targets for all changes. ClientDetectedCloudStorageQuotaExceeded: 'File size (155484) exceeds available space (-43553) on server.', recovery targets: set([])
2021-07-21 18:38:38,598 +0900 ERROR pid=12760 12468:Worker-1        fatal_exceptions.py:69 Ignoring non-fatal error: ClientDetectedCloudStorageQuotaExceeded: ClientDetectedCloudStorageQuotaExceeded: 'File size (155484) exceeds available space (-43553) on server.', recovery targets: set([LocalID(inode=1125899906907860L, volume='serial:3188545052'), LocalID(inode=1125899906907862L, volume='serial:3188545052')]), Traceback:
  File "common\workers.py", line 201, in Process
  File "common\persistence\sqlite.py", line 141, in Wrapper
  File "common\workers.py", line 359, in _ProcessChanges
  File "common\worker\uploads.py", line 958, in Execute
  File "common\worker\uploads.py", line 1108, in _UploadCreate
  File "common\worker\workers_helper.py", line 406, in CreateCloudFile
  File "common\worker\workers_helper.py", line 372, in EnforceRemainingQuota

2021-07-21 18:38:38,604 +0900 ERROR pid=12760 12460:Worker-2        blacklist.py:286 The following request has been blacklisted FSChange(Direction.UPLOAD, Action.CREATE, local_id=LocalID(inode=1970324837039899L, volume='serial:3188545052'), path=u'\\\\?\\C:\\workspace\\\ub179\ud654\\cakd3\\.git\\objects\\eb', name=u'a37d954ce9f9dea455806a33dd557217012837', parent_local_id=LocalID(inode=844424930197272L, volume='serial:3188545052'), is_folder=False, modified=1625291357, size=436, generator_module=Generator.LOCAL_EVENT_GENERATOR, shared=False, hash=-130817987, row_id=2103) Because of exception: ClientDetectedCloudStorageQuotaExceeded: 'File size (436) exceeds available space (-43553) on server.', recovery targets: set([LocalID(inode=844424930197272L, volume='serial:3188545052'), LocalID(inode=1970324837039899L, volume='serial:3188545052')])
2021-07-21 18:38:38,604 +0900 INFO pid=12760 12460:Worker-2        change_buffer_entry.py:215 Replacing entry in change buffer: ChangeBufferEntry(state=IN_PROGRESS, fschange=FSChange(Direction.UPLOAD, Action.CREATE, local_id=LocalID(inode=1970324837039899L, volume='serial:3188545052'), path=u'\\\\?\\C:\\workspace\\\ub179\ud654\\cakd3\\.git\\objects\\eb', name=u'a37d954ce9f9dea455806a33dd557217012837', parent_local_id=LocalID(inode=844424930197272L, volume='serial:3188545052'), is_folder=False, modified=1625291357, size=436, generator_module=Generator.LOCAL_EVENT_GENERATOR, shared=False, row_id=2103), time=190561.406, row_id=1916)->ChangeBufferEntry(state=BLACKLISTED, fschange=FSChange(Direction.UPLOAD, Action.CREATE, local_id=LocalID(inode=1970324837039899L, volume='serial:3188545052'), path=u'\\\\?\\C:\\workspace\\\ub179\ud654\\cakd3\\.git\\objects\\eb', name=u'a37d954ce9f9dea455806a33dd557217012837', parent_local_id=LocalID(inode=844424930197272L, volume='serial:3188545052'), is_folder=False, modified=1625291357, size=436, generator_module=Generator.LOCAL_EVENT_GENERATOR, shared=False, row_id=2103), blacklist_info=BlacklistInfoSub(key=u'\\\\?\\C:\\workspace\\\ub179\ud654\\cakd3\\.git\\objects\\eb\\a37d954ce9f9dea455806a33dd557217012837', fullname=u'\\\\?\\C:\\workspace\\\ub179\ud654\\cakd3\\.git\\objects\\eb\\a37d954ce9f9dea455806a33dd557217012837', direction=<Direction.UPLOAD: 'UPLOAD'>, failure=ClientDetectedCloudStorageQuotaExceeded(), entry_time=190691.593, url=None, is_folder=False, action=<Action.CREATE: 'CREATE'>), time=190561.406, row_id=1916)
2021-07-21 18:38:38,651 +0900 ERROR pid=12760 12468:Worker-1        blacklist.py:286 The following request has been blacklisted FSChange(Direction.UPLOAD, Action.CREATE, local_id=LocalID(inode=1125899906907862L, volume='serial:3188545052'), path=u'\\\\?\\C:\\workspace\\\ub179\ud654\\cakd3\\.git\\objects\\d3', name=u'd4368936657b570bf81b9bd87d02f29cfc1179', parent_local_id=LocalID(inode=1125899906907860L, volume='serial:3188545052'), is_folder=False, modified=1625291484, size=155484, generator_module=Generator.LOCAL_EVENT_GENERATOR, shared=False, hash=-9935624, row_id=2105) Because of exception: ClientDetectedCloudStorageQuotaExceeded: 'File size (155484) exceeds available space (-43553) on server.', recovery targets: set([LocalID(inode=1125899906907860L, volume='serial:3188545052'), LocalID(inode=1125899906907862L, volume='serial:3188545052')])
2021-07-21 18:38:38,651 +0900 INFO pid=12760 12468:Worker-1        change_buffer_entry.py:215 Replacing entry in change buffer: ChangeBufferEntry(state=IN_PROGRESS, fschange=FSChange(Direction.UPLOAD, Action.CREATE, local_id=LocalID(inode=1125899906907862L, volume='serial:3188545052'), path=u'\\\\?\\C:\\workspace\\\ub179\ud654\\cakd3\\.git\\objects\\d3', name=u'd4368936657b570bf81b9bd87d02f29cfc1179', parent_local_id=LocalID(inode=1125899906907860L, volume='serial:3188545052'), is_folder=False, modified=1625291484, size=155484, generator_module=Generator.LOCAL_EVENT_GENERATOR, shared=False, row_id=2105), time=190561.453, row_id=1918)->ChangeBufferEntry(state=BLACKLISTED, fschange=FSChange(Direction.UPLOAD, Action.CREATE, local_id=LocalID(inode=1125899906907862L, volume='serial:3188545052'), path=u'\\\\?\\C:\\workspace\\\ub179\ud654\\cakd3\\.git\\objects\\d3', name=u'd4368936657b570bf81b9bd87d02f29cfc1179', parent_local_id=LocalID(inode=1125899906907860L, volume='serial:3188545052'), is_folder=False, modified=1625291484, size=155484, generator_module=Generator.LOCAL_EVENT_GENERATOR, shared=False, row_id=2105), blacklist_info=BlacklistInfoSub(key=u'\\\\?\\C:\\workspace\\\ub179\ud654\\cakd3\\.git\\objects\\d3\\d4368936657b570bf81b9bd87d02f29cfc1179', fullname=u'\\\\?\\C:\\workspace\\\ub179\ud654\\cakd3\\.git\\objects\\d3\\d4368936657b570bf81b9bd87d02f29cfc1179', direction=<Direction.UPLOAD: 'UPLOAD'>, failure=ClientDetectedCloudStorageQuotaExceeded(), entry_time=190691.65600000002, url=None, is_folder=False, action=<Action.CREATE: 'CREATE'>), time=190561.453, row_id=1918)
2021-07-21 18:38:38,709 +0900 INFO pid=12760 10252:Worker-0        workers.py:192 Worker starting on [FSChange(Direction.UPLOAD, Action.CREATE, local_id=LocalID(inode=1407374883618519L, volume='serial:3188545052'), path=u'\\\\?\\C:\\workspace\\\ub179\ud654\\cakd3\\.git\\objects\\d3', name=u'd4aabd0bc1e5030ee7d2a4f7ffd4ee2623d155', parent_local_id=LocalID(inode=1125899906907860L, volume='serial:3188545052'), is_folder=False, modified=1625291484, size=51259, generator_module=Generator.LOCAL_EVENT_GENERATOR, shared=False, hash=-1182514705, row_id=2106)]
2021-07-21 18:38:38,710 +0900 INFO pid=12760 10252:Worker-0        doc_id_provider.py:126 Returning doc ID '1U1kDxIHOwJmpljZCiiFLHkaYJzSJs1Bc'. 2856 IDs left in store.
2021-07-21 18:38:38,711 +0900 INFO pid=12760 10252:Worker-0        snapshot_sqlite.py:647 Adding pre_mapping local_id=LocalID(inode=1407374883618519L, volume='serial:3188545052'), doc_id=1U1kDxIHOwJmpljZCiiFLHkaYJzSJs1Bc
2021-07-21 18:38:38,713 +0900 ERROR pid=12760 10252:Worker-0        workers.py:234 Exception while processing change [FSChange(Direction.UPLOAD, Action.CREATE, local_id=LocalID(inode=1407374883618519L, volume='serial:3188545052'), path=u'\\\\?\\C:\\workspace\\\ub179\ud654\\cakd3\\.git\\objects\\d3', name=u'd4aabd0bc1e5030ee7d2a4f7ffd4ee2623d155', parent_local_id=LocalID(inode=1125899906907860L, volume='serial:3188545052'), is_folder=False, modified=1625291484, size=51259, generator_module=Generator.LOCAL_EVENT_GENERATOR, shared=False, hash=-1182514705, row_id=2106)]
Traceback (most recent call last):
  File "common\workers.py", line 201, in Process
  File "common\persistence\sqlite.py", line 141, in Wrapper
  File "common\workers.py", line 359, in _ProcessChanges
  File "common\worker\uploads.py", line 958, in Execute
  File "common\worker\uploads.py", line 1108, in _UploadCreate
  File "common\worker\workers_helper.py", line 406, in CreateCloudFile
  File "common\worker\workers_helper.py", line 372, in EnforceRemainingQuota
ClientDetectedCloudStorageQuotaExceeded: ClientDetectedCloudStorageQuotaExceeded: 'File size (51259) exceeds available space (-43553) on server.', recovery targets: set([])
2021-07-21 18:38:38,714 +0900 WARNING pid=12760 10252:Worker-0        workers.py:422 Setting recovery_targets for all changes. ClientDetectedCloudStorageQuotaExceeded: 'File size (51259) exceeds available space (-43553) on server.', recovery targets: set([])
2021-07-21 18:38:38,714 +0900 ERROR pid=12760 10252:Worker-0        fatal_exceptions.py:69 Ignoring non-fatal error: ClientDetectedCloudStorageQuotaExceeded: ClientDetectedCloudStorageQuotaExceeded: 'File size (51259) exceeds available space (-43553) on server.', recovery targets: set([LocalID(inode=1407374883618519L, volume='serial:3188545052'), LocalID(inode=1125899906907860L, volume='serial:3188545052')]), Traceback:
  File "common\workers.py", line 201, in Process
  File "common\persistence\sqlite.py", line 141, in Wrapper
  File "common\workers.py", line 359, in _ProcessChanges
  File "common\worker\uploads.py", line 958, in Execute
  File "common\worker\uploads.py", line 1108, in _UploadCreate
  File "common\worker\workers_helper.py", line 406, in CreateCloudFile
  File "common\worker\workers_helper.py", line 372, in EnforceRemainingQuota

2021-07-21 18:38:38,724 +0900 ERROR pid=12760 10252:Worker-0        blacklist.py:286 The following request has been blacklisted FSChange(Direction.UPLOAD, Action.CREATE, local_id=LocalID(inode=1407374883618519L, volume='serial:3188545052'), path=u'\\\\?\\C:\\workspace\\\ub179\ud654\\cakd3\\.git\\objects\\d3', name=u'd4aabd0bc1e5030ee7d2a4f7ffd4ee2623d155', parent_local_id=LocalID(inode=1125899906907860L, volume='serial:3188545052'), is_folder=False, modified=1625291484, size=51259, generator_module=Generator.LOCAL_EVENT_GENERATOR, shared=False, hash=-1182514705, row_id=2106) Because of exception: ClientDetectedCloudStorageQuotaExceeded: 'File size (51259) exceeds available space (-43553) on server.', recovery targets: set([LocalID(inode=1407374883618519L, volume='serial:3188545052'), LocalID(inode=1125899906907860L, volume='serial:3188545052')])
2021-07-21 18:38:38,726 +0900 INFO pid=12760 10252:Worker-0        change_buffer_entry.py:215 Replacing entry in change buffer: ChangeBufferEntry(state=IN_PROGRESS, fschange=FSChange(Direction.UPLOAD, Action.CREATE, local_id=LocalID(inode=1407374883618519L, volume='serial:3188545052'), path=u'\\\\?\\C:\\workspace\\\ub179\ud654\\cakd3\\.git\\objects\\d3', name=u'd4aabd0bc1e5030ee7d2a4f7ffd4ee2623d155', parent_local_id=LocalID(inode=1125899906907860L, volume='serial:3188545052'), is_folder=False, modified=1625291484, size=51259, generator_module=Generator.LOCAL_EVENT_GENERATOR, shared=False, row_id=2106), time=190561.546, row_id=1919)->ChangeBufferEntry(state=BLACKLISTED, fschange=FSChange(Direction.UPLOAD, Action.CREATE, local_id=LocalID(inode=1407374883618519L, volume='serial:3188545052'), path=u'\\\\?\\C:\\workspace\\\ub179\ud654\\cakd3\\.git\\objects\\d3', name=u'd4aabd0bc1e5030ee7d2a4f7ffd4ee2623d155', parent_local_id=LocalID(inode=1125899906907860L, volume='serial:3188545052'), is_folder=False, modified=1625291484, size=51259, generator_module=Generator.LOCAL_EVENT_GENERATOR, shared=False, row_id=2106), blacklist_info=BlacklistInfoSub(key=u'\\\\?\\C:\\workspace\\\ub179\ud654\\cakd3\\.git\\objects\\d3\\d4aabd0bc1e5030ee7d2a4f7ffd4ee2623d155', fullname=u'\\\\?\\C:\\workspace\\\ub179\ud654\\cakd3\\.git\\objects\\d3\\d4aabd0bc1e5030ee7d2a4f7ffd4ee2623d155', direction=<Direction.UPLOAD: 'UPLOAD'>, failure=ClientDetectedCloudStorageQuotaExceeded(), entry_time=190691.718, url=None, is_folder=False, action=<Action.CREATE: 'CREATE'>), time=190561.546, row_id=1919)
2021-07-21 18:38:38,789 +0900 INFO pid=12760 12460:Worker-2        workers.py:192 Worker starting on [FSChange(Direction.UPLOAD, Action.CREATE, local_id=LocalID(inode=1407374883618517L, volume='serial:3188545052'), path=u'\\\\?\\C:\\workspace\\\ub179\ud654\\cakd3\\.git\\objects\\d3', name=u'3a058634bef538a66ca06f91bd50f1c737063c', parent_local_id=LocalID(inode=1125899906907860L, volume='serial:3188545052'), is_folder=False, modified=1626858111, size=4419, generator_module=Generator.LOCAL_EVENT_GENERATOR, shared=False, hash=-1080240694, row_id=2107)]
2021-07-21 18:38:38,792 +0900 INFO pid=12760 12460:Worker-2        doc_id_provider.py:126 Returning doc ID '1qFV0jbQ6YncW0JJy4dlJtBm9lsKZvr_g'. 2855 IDs left in store.
2021-07-21 18:38:38,792 +0900 INFO pid=12760 12460:Worker-2        snapshot_sqlite.py:647 Adding pre_mapping local_id=LocalID(inode=1407374883618517L, volume='serial:3188545052'), doc_id=1qFV0jbQ6YncW0JJy4dlJtBm9lsKZvr_g
2021-07-21 18:38:38,796 +0900 ERROR pid=12760 12460:Worker-2        workers.py:234 Exception while processing change [FSChange(Direction.UPLOAD, Action.CREATE, local_id=LocalID(inode=1407374883618517L, volume='serial:3188545052'), path=u'\\\\?\\C:\\workspace\\\ub179\ud654\\cakd3\\.git\\objects\\d3', name=u'3a058634bef538a66ca06f91bd50f1c737063c', parent_local_id=LocalID(inode=1125899906907860L, volume='serial:3188545052'), is_folder=False, modified=1626858111, size=4419, generator_module=Generator.LOCAL_EVENT_GENERATOR, shared=False, hash=-1080240694, row_id=2107)]
Traceback (most recent call last):
  File "common\workers.py", line 201, in Process
  File "common\persistence\sqlite.py", line 141, in Wrapper
  File "common\workers.py", line 359, in _ProcessChanges
  File "common\worker\uploads.py", line 958, in Execute
  File "common\worker\uploads.py", line 1108, in _UploadCreate
  File "common\worker\workers_helper.py", line 406, in CreateCloudFile
  File "common\worker\workers_helper.py", line 372, in EnforceRemainingQuota
ClientDetectedCloudStorageQuotaExceeded: ClientDetectedCloudStorageQuotaExceeded: 'File size (4419) exceeds available space (-43553) on server.', recovery targets: set([])
2021-07-21 18:38:38,796 +0900 WARNING pid=12760 12460:Worker-2        workers.py:422 Setting recovery_targets for all changes. ClientDetectedCloudStorageQuotaExceeded: 'File size (4419) exceeds available space (-43553) on server.', recovery targets: set([])
2021-07-21 18:38:38,796 +0900 ERROR pid=12760 12460:Worker-2        fatal_exceptions.py:69 Ignoring non-fatal error: ClientDetectedCloudStorageQuotaExceeded: ClientDetectedCloudStorageQuotaExceeded: 'File size (4419) exceeds available space (-43553) on server.', recovery targets: set([LocalID(inode=1407374883618517L, volume='serial:3188545052'), LocalID(inode=1125899906907860L, volume='serial:3188545052')]), Traceback:
  File "common\workers.py", line 201, in Process
  File "common\persistence\sqlite.py", line 141, in Wrapper
  File "common\workers.py", line 359, in _ProcessChanges
  File "common\worker\uploads.py", line 958, in Execute
  File "common\worker\uploads.py", line 1108, in _UploadCreate
  File "common\worker\workers_helper.py", line 406, in CreateCloudFile
  File "common\worker\workers_helper.py", line 372, in EnforceRemainingQuota

2021-07-21 18:38:38,815 +0900 INFO pid=12760 12468:Worker-1        workers.py:192 Worker starting on [FSChange(Direction.UPLOAD, Action.CREATE, local_id=LocalID(inode=1970324837039818L, volume='serial:3188545052'), path=u'\\\\?\\C:\\workspace\\\ub179\ud654\\cakd3\\.git\\objects\\d0', name=u'344a24687d1a1009824079766235025df9b93a', parent_local_id=LocalID(inode=1407374883618503L, volume='serial:3188545052'), is_folder=False, modified=1625291484, size=52, generator_module=Generator.LOCAL_EVENT_GENERATOR, shared=False, hash=-776349434, row_id=2109)]
2021-07-21 18:38:38,816 +0900 INFO pid=12760 12468:Worker-1        doc_id_provider.py:126 Returning doc ID '1oJVa0ymBk3SDTlO8xwL5ZJPDgqqAIXq7'. 2854 IDs left in store.
2021-07-21 18:38:38,818 +0900 INFO pid=12760 12468:Worker-1        snapshot_sqlite.py:647 Adding pre_mapping local_id=LocalID(inode=1970324837039818L, volume='serial:3188545052'), doc_id=1oJVa0ymBk3SDTlO8xwL5ZJPDgqqAIXq7
2021-07-21 18:38:38,819 +0900 ERROR pid=12760 12468:Worker-1        workers.py:234 Exception while processing change [FSChange(Direction.UPLOAD, Action.CREATE, local_id=LocalID(inode=1970324837039818L, volume='serial:3188545052'), path=u'\\\\?\\C:\\workspace\\\ub179\ud654\\cakd3\\.git\\objects\\d0', name=u'344a24687d1a1009824079766235025df9b93a', parent_local_id=LocalID(inode=1407374883618503L, volume='serial:3188545052'), is_folder=False, modified=1625291484, size=52, generator_module=Generator.LOCAL_EVENT_GENERATOR, shared=False, hash=-776349434, row_id=2109)]
Traceback (most recent call last):
  File "common\workers.py", line 201, in Process
  File "common\persistence\sqlite.py", line 141, in Wrapper
  File "common\workers.py", line 359, in _ProcessChanges
  File "common\worker\uploads.py", line 958, in Execute
  File "common\worker\uploads.py", line 1108, in _UploadCreate
  File "common\worker\workers_helper.py", line 406, in CreateCloudFile
  File "common\worker\workers_helper.py", line 372, in EnforceRemainingQuota
ClientDetectedCloudStorageQuotaExceeded: ClientDetectedCloudStorageQuotaExceeded: 'File size (52) exceeds available space (-43553) on server.', recovery targets: set([])
2021-07-21 18:38:38,821 +0900 WARNING pid=12760 12468:Worker-1        workers.py:422 Setting recovery_targets for all changes. ClientDetectedCloudStorageQuotaExceeded: 'File size (52) exceeds available space (-43553) on server.', recovery targets: set([])
2021-07-21 18:38:38,821 +0900 ERROR pid=12760 12468:Worker-1        fatal_exceptions.py:69 Ignoring non-fatal error: ClientDetectedCloudStorageQuotaExceeded: ClientDetectedCloudStorageQuotaExceeded: 'File size (52) exceeds available space (-43553) on server.', recovery targets: set([LocalID(inode=1407374883618503L, volume='serial:3188545052'), LocalID(inode=1970324837039818L, volume='serial:3188545052')]), Traceback:
  File "common\workers.py", line 201, in Process
  File "common\persistence\sqlite.py", line 141, in Wrapper
  File "common\workers.py", line 359, in _ProcessChanges
  File "common\worker\uploads.py", line 958, in Execute
  File "common\worker\uploads.py", line 1108, in _UploadCreate
  File "common\worker\workers_helper.py", line 406, in CreateCloudFile
  File "common\worker\workers_helper.py", line 372, in EnforceRemainingQuota

2021-07-21 18:38:38,825 +0900 ERROR pid=12760 12460:Worker-2        blacklist.py:286 The following request has been blacklisted FSChange(Direction.UPLOAD, Action.CREATE, local_id=LocalID(inode=1407374883618517L, volume='serial:3188545052'), path=u'\\\\?\\C:\\workspace\\\ub179\ud654\\cakd3\\.git\\objects\\d3', name=u'3a058634bef538a66ca06f91bd50f1c737063c', parent_local_id=LocalID(inode=1125899906907860L, volume='serial:3188545052'), is_folder=False, modified=1626858111, size=4419, generator_module=Generator.LOCAL_EVENT_GENERATOR, shared=False, hash=-1080240694, row_id=2107) Because of exception: ClientDetectedCloudStorageQuotaExceeded: 'File size (4419) exceeds available space (-43553) on server.', recovery targets: set([LocalID(inode=1407374883618517L, volume='serial:3188545052'), LocalID(inode=1125899906907860L, volume='serial:3188545052')])
2021-07-21 18:38:38,825 +0900 INFO pid=12760 12460:Worker-2        change_buffer_entry.py:215 Replacing entry in change buffer: ChangeBufferEntry(state=IN_PROGRESS, fschange=FSChange(Direction.UPLOAD, Action.CREATE, local_id=LocalID(inode=1407374883618517L, volume='serial:3188545052'), path=u'\\\\?\\C:\\workspace\\\ub179\ud654\\cakd3\\.git\\objects\\d3', name=u'3a058634bef538a66ca06f91bd50f1c737063c', parent_local_id=LocalID(inode=1125899906907860L, volume='serial:3188545052'), is_folder=False, modified=1626858111, size=4419, generator_module=Generator.LOCAL_EVENT_GENERATOR, shared=False, row_id=2107), time=190561.578, row_id=1920)->ChangeBufferEntry(state=BLACKLISTED, fschange=FSChange(Direction.UPLOAD, Action.CREATE, local_id=LocalID(inode=1407374883618517L, volume='serial:3188545052'), path=u'\\\\?\\C:\\workspace\\\ub179\ud654\\cakd3\\.git\\objects\\d3', name=u'3a058634bef538a66ca06f91bd50f1c737063c', parent_local_id=LocalID(inode=1125899906907860L, volume='serial:3188545052'), is_folder=False, modified=1626858111, size=4419, generator_module=Generator.LOCAL_EVENT_GENERATOR, shared=False, row_id=2107), blacklist_info=BlacklistInfoSub(key=u'\\\\?\\C:\\workspace\\\ub179\ud654\\cakd3\\.git\\objects\\d3\\3a058634bef538a66ca06f91bd50f1c737063c', fullname=u'\\\\?\\C:\\workspace\\\ub179\ud654\\cakd3\\.git\\objects\\d3\\3a058634bef538a66ca06f91bd50f1c737063c', direction=<Direction.UPLOAD: 'UPLOAD'>, failure=ClientDetectedCloudStorageQuotaExceeded(), entry_time=190691.828, url=None, is_folder=False, action=<Action.CREATE: 'CREATE'>), time=190561.578, row_id=1920)
2021-07-21 18:38:38,871 +0900 ERROR pid=12760 12468:Worker-1        blacklist.py:286 The following request has been blacklisted FSChange(Direction.UPLOAD, Action.CREATE, local_id=LocalID(inode=1970324837039818L, volume='serial:3188545052'), path=u'\\\\?\\C:\\workspace\\\ub179\ud654\\cakd3\\.git\\objects\\d0', name=u'344a24687d1a1009824079766235025df9b93a', parent_local_id=LocalID(inode=1407374883618503L, volume='serial:3188545052'), is_folder=False, modified=1625291484, size=52, generator_module=Generator.LOCAL_EVENT_GENERATOR, shared=False, hash=-776349434, row_id=2109) Because of exception: ClientDetectedCloudStorageQuotaExceeded: 'File size (52) exceeds available space (-43553) on server.', recovery targets: set([LocalID(inode=1407374883618503L, volume='serial:3188545052'), LocalID(inode=1970324837039818L, volume='serial:3188545052')])
2021-07-21 18:38:38,871 +0900 INFO pid=12760 12468:Worker-1        change_buffer_entry.py:215 Replacing entry in change buffer: ChangeBufferEntry(state=IN_PROGRESS, fschange=FSChange(Direction.UPLOAD, Action.CREATE, local_id=LocalID(inode=1970324837039818L, volume='serial:3188545052'), path=u'\\\\?\\C:\\workspace\\\ub179\ud654\\cakd3\\.git\\objects\\d0', name=u'344a24687d1a1009824079766235025df9b93a', parent_local_id=LocalID(inode=1407374883618503L, volume='serial:3188545052'), is_folder=False, modified=1625291484, size=52, generator_module=Generator.LOCAL_EVENT_GENERATOR, shared=False, row_id=2109), time=190561.625, row_id=1922)->ChangeBufferEntry(state=BLACKLISTED, fschange=FSChange(Direction.UPLOAD, Action.CREATE, local_id=LocalID(inode=1970324837039818L, volume='serial:3188545052'), path=u'\\\\?\\C:\\workspace\\\ub179\ud654\\cakd3\\.git\\objects\\d0', name=u'344a24687d1a1009824079766235025df9b93a', parent_local_id=LocalID(inode=1407374883618503L, volume='serial:3188545052'), is_folder=False, modified=1625291484, size=52, generator_module=Generator.LOCAL_EVENT_GENERATOR, shared=False, row_id=2109), blacklist_info=BlacklistInfoSub(key=u'\\\\?\\C:\\workspace\\\ub179\ud654\\cakd3\\.git\\objects\\d0\\344a24687d1a1009824079766235025df9b93a', fullname=u'\\\\?\\C:\\workspace\\\ub179\ud654\\cakd3\\.git\\objects\\d0\\344a24687d1a1009824079766235025df9b93a', direction=<Direction.UPLOAD: 'UPLOAD'>, failure=ClientDetectedCloudStorageQuotaExceeded(), entry_time=190691.875, url=None, is_folder=False, action=<Action.CREATE: 'CREATE'>), time=190561.625, row_id=1922)
2021-07-21 18:38:38,930 +0900 INFO pid=12760 10252:Worker-0        workers.py:192 Worker starting on [FSChange(Direction.UPLOAD, Action.CREATE, local_id=LocalID(inode=1407374883618507L, volume='serial:3188545052'), path=u'\\\\?\\C:\\workspace\\\ub179\ud654\\cakd3\\.git\\objects\\d0', name=u'3a2ca2eaf84f5b6683f80c93642d0a2ccf70d8', parent_local_id=LocalID(inode=1407374883618503L, volume='serial:3188545052'), is_folder=False, modified=1625291484, size=124871, generator_module=Generator.LOCAL_EVENT_GENERATOR, shared=False, hash=-524461062, row_id=2110)]
2021-07-21 18:38:38,931 +0900 INFO pid=12760 10252:Worker-0        doc_id_provider.py:126 Returning doc ID '1-xSNQamPJkO98Mk0hGopxtpUYwpokP8A'. 2853 IDs left in store.
2021-07-21 18:38:38,931 +0900 INFO pid=12760 10252:Worker-0        snapshot_sqlite.py:647 Adding pre_mapping local_id=LocalID(inode=1407374883618507L, volume='serial:3188545052'), doc_id=1-xSNQamPJkO98Mk0hGopxtpUYwpokP8A
2021-07-21 18:38:38,934 +0900 ERROR pid=12760 10252:Worker-0        workers.py:234 Exception while processing change [FSChange(Direction.UPLOAD, Action.CREATE, local_id=LocalID(inode=1407374883618507L, volume='serial:3188545052'), path=u'\\\\?\\C:\\workspace\\\ub179\ud654\\cakd3\\.git\\objects\\d0', name=u'3a2ca2eaf84f5b6683f80c93642d0a2ccf70d8', parent_local_id=LocalID(inode=1407374883618503L, volume='serial:3188545052'), is_folder=False, modified=1625291484, size=124871, generator_module=Generator.LOCAL_EVENT_GENERATOR, shared=False, hash=-524461062, row_id=2110)]
Traceback (most recent call last):
  File "common\workers.py", line 201, in Process
  File "common\persistence\sqlite.py", line 141, in Wrapper
  File "common\workers.py", line 359, in _ProcessChanges
  File "common\worker\uploads.py", line 958, in Execute
  File "common\worker\uploads.py", line 1108, in _UploadCreate
  File "common\worker\workers_helper.py", line 406, in CreateCloudFile
  File "common\worker\workers_helper.py", line 372, in EnforceRemainingQuota
ClientDetectedCloudStorageQuotaExceeded: ClientDetectedCloudStorageQuotaExceeded: 'File size (124871) exceeds available space (-43553) on server.', recovery targets: set([])
2021-07-21 18:38:38,936 +0900 WARNING pid=12760 10252:Worker-0        workers.py:422 Setting recovery_targets for all changes. ClientDetectedCloudStorageQuotaExceeded: 'File size (124871) exceeds available space (-43553) on server.', recovery targets: set([])
2021-07-21 18:38:38,937 +0900 ERROR pid=12760 10252:Worker-0        fatal_exceptions.py:69 Ignoring non-fatal error: ClientDetectedCloudStorageQuotaExceeded: ClientDetectedCloudStorageQuotaExceeded: 'File size (124871) exceeds available space (-43553) on server.', recovery targets: set([LocalID(inode=1407374883618503L, volume='serial:3188545052'), LocalID(inode=1407374883618507L, volume='serial:3188545052')]), Traceback:
  File "common\workers.py", line 201, in Process
  File "common\persistence\sqlite.py", line 141, in Wrapper
  File "common\workers.py", line 359, in _ProcessChanges
  File "common\worker\uploads.py", line 958, in Execute
  File "common\worker\uploads.py", line 1108, in _UploadCreate
  File "common\worker\workers_helper.py", line 406, in CreateCloudFile
  File "common\worker\workers_helper.py", line 372, in EnforceRemainingQuota

2021-07-21 18:38:38,947 +0900 ERROR pid=12760 10252:Worker-0        blacklist.py:286 The following request has been blacklisted FSChange(Direction.UPLOAD, Action.CREATE, local_id=LocalID(inode=1407374883618507L, volume='serial:3188545052'), path=u'\\\\?\\C:\\workspace\\\ub179\ud654\\cakd3\\.git\\objects\\d0', name=u'3a2ca2eaf84f5b6683f80c93642d0a2ccf70d8', parent_local_id=LocalID(inode=1407374883618503L, volume='serial:3188545052'), is_folder=False, modified=1625291484, size=124871, generator_module=Generator.LOCAL_EVENT_GENERATOR, shared=False, hash=-524461062, row_id=2110) Because of exception: ClientDetectedCloudStorageQuotaExceeded: 'File size (124871) exceeds available space (-43553) on server.', recovery targets: set([LocalID(inode=1407374883618503L, volume='serial:3188545052'), LocalID(inode=1407374883618507L, volume='serial:3188545052')])
2021-07-21 18:38:38,947 +0900 INFO pid=12760 10252:Worker-0        change_buffer_entry.py:215 Replacing entry in change buffer: ChangeBufferEntry(state=IN_PROGRESS, fschange=FSChange(Direction.UPLOAD, Action.CREATE, local_id=LocalID(inode=1407374883618507L, volume='serial:3188545052'), path=u'\\\\?\\C:\\workspace\\\ub179\ud654\\cakd3\\.git\\objects\\d0', name=u'3a2ca2eaf84f5b6683f80c93642d0a2ccf70d8', parent_local_id=LocalID(inode=1407374883618503L, volume='serial:3188545052'), is_folder=False, modified=1625291484, size=124871, generator_module=Generator.LOCAL_EVENT_GENERATOR, shared=False, row_id=2110), time=190561.656, row_id=1923)->ChangeBufferEntry(state=BLACKLISTED, fschange=FSChange(Direction.UPLOAD, Action.CREATE, local_id=LocalID(inode=1407374883618507L, volume='serial:3188545052'), path=u'\\\\?\\C:\\workspace\\\ub179\ud654\\cakd3\\.git\\objects\\d0', name=u'3a2ca2eaf84f5b6683f80c93642d0a2ccf70d8', parent_local_id=LocalID(inode=1407374883618503L, volume='serial:3188545052'), is_folder=False, modified=1625291484, size=124871, generator_module=Generator.LOCAL_EVENT_GENERATOR, shared=False, row_id=2110), blacklist_info=BlacklistInfoSub(key=u'\\\\?\\C:\\workspace\\\ub179\ud654\\cakd3\\.git\\objects\\d0\\3a2ca2eaf84f5b6683f80c93642d0a2ccf70d8', fullname=u'\\\\?\\C:\\workspace\\\ub179\ud654\\cakd3\\.git\\objects\\d0\\3a2ca2eaf84f5b6683f80c93642d0a2ccf70d8', direction=<Direction.UPLOAD: 'UPLOAD'>, failure=ClientDetectedCloudStorageQuotaExceeded(), entry_time=190691.937, url=None, is_folder=False, action=<Action.CREATE: 'CREATE'>), time=190561.656, row_id=1923)
2021-07-21 18:38:39,013 +0900 INFO pid=12760 12460:Worker-2        workers.py:192 Worker starting on [FSChange(Direction.UPLOAD, Action.CREATE, local_id=LocalID(inode=1125899906907962L, volume='serial:3188545052'), path=u'\\\\?\\C:\\workspace\\\ub179\ud654\\cakd3\\.git\\objects\\f5', name=u'ffcb4432db602e83d3d928213c6d5fd5a7216b', parent_local_id=LocalID(inode=844424930197303L, volume='serial:3188545052'), is_folder=False, modified=1626858110, size=18115, generator_module=Generator.LOCAL_EVENT_GENERATOR, shared=False, hash=-1657478157, row_id=2112)]
2021-07-21 18:38:39,016 +0900 INFO pid=12760 12460:Worker-2        doc_id_provider.py:126 Returning doc ID '1kTrpcquCxZz_Qm6m1JcRGSdEB2e1KvtC'. 2852 IDs left in store.
2021-07-21 18:38:39,016 +0900 INFO pid=12760 12460:Worker-2        snapshot_sqlite.py:647 Adding pre_mapping local_id=LocalID(inode=1125899906907962L, volume='serial:3188545052'), doc_id=1kTrpcquCxZz_Qm6m1JcRGSdEB2e1KvtC
2021-07-21 18:38:39,019 +0900 ERROR pid=12760 12460:Worker-2        workers.py:234 Exception while processing change [FSChange(Direction.UPLOAD, Action.CREATE, local_id=LocalID(inode=1125899906907962L, volume='serial:3188545052'), path=u'\\\\?\\C:\\workspace\\\ub179\ud654\\cakd3\\.git\\objects\\f5', name=u'ffcb4432db602e83d3d928213c6d5fd5a7216b', parent_local_id=LocalID(inode=844424930197303L, volume='serial:3188545052'), is_folder=False, modified=1626858110, size=18115, generator_module=Generator.LOCAL_EVENT_GENERATOR, shared=False, hash=-1657478157, row_id=2112)]
Traceback (most recent call last):
  File "common\workers.py", line 201, in Process
  File "common\persistence\sqlite.py", line 141, in Wrapper
  File "common\workers.py", line 359, in _ProcessChanges
  File "common\worker\uploads.py", line 958, in Execute
  File "common\worker\uploads.py", line 1108, in _UploadCreate
  File "common\worker\workers_helper.py", line 406, in CreateCloudFile
  File "common\worker\workers_helper.py", line 372, in EnforceRemainingQuota
ClientDetectedCloudStorageQuotaExceeded: ClientDetectedCloudStorageQuotaExceeded: 'File size (18115) exceeds available space (-43553) on server.', recovery targets: set([])
2021-07-21 18:38:39,019 +0900 WARNING pid=12760 12460:Worker-2        workers.py:422 Setting recovery_targets for all changes. ClientDetectedCloudStorageQuotaExceeded: 'File size (18115) exceeds available space (-43553) on server.', recovery targets: set([])
2021-07-21 18:38:39,019 +0900 ERROR pid=12760 12460:Worker-2        fatal_exceptions.py:69 Ignoring non-fatal error: ClientDetectedCloudStorageQuotaExceeded: ClientDetectedCloudStorageQuotaExceeded: 'File size (18115) exceeds available space (-43553) on server.', recovery targets: set([LocalID(inode=844424930197303L, volume='serial:3188545052'), LocalID(inode=1125899906907962L, volume='serial:3188545052')]), Traceback:
  File "common\workers.py", line 201, in Process
  File "common\persistence\sqlite.py", line 141, in Wrapper
  File "common\workers.py", line 359, in _ProcessChanges
  File "common\worker\uploads.py", line 958, in Execute
  File "common\worker\uploads.py", line 1108, in _UploadCreate
  File "common\worker\workers_helper.py", line 406, in CreateCloudFile
  File "common\worker\workers_helper.py", line 372, in EnforceRemainingQuota

2021-07-21 18:38:39,039 +0900 INFO pid=12760 12468:Worker-1        workers.py:192 Worker starting on [FSChange(Direction.UPLOAD, Action.CREATE, local_id=LocalID(inode=844424930197304L, volume='serial:3188545052'), path=u'\\\\?\\C:\\workspace\\\ub179\ud654\\cakd3\\.git\\objects\\f5', name=u'0c1e325d869d51b59726f9f940a8c6262d1283', parent_local_id=LocalID(inode=844424930197303L, volume='serial:3188545052'), is_folder=False, modified=1625291484, size=5224, generator_module=Generator.LOCAL_EVENT_GENERATOR, shared=False, hash=-849481687, row_id=2113)]
2021-07-21 18:38:39,040 +0900 INFO pid=12760 12468:Worker-1        doc_id_provider.py:126 Returning doc ID '1EplMEKPojPbNMYrghvbVWSKlapuTgOC-'. 2851 IDs left in store.
2021-07-21 18:38:39,040 +0900 INFO pid=12760 12468:Worker-1        snapshot_sqlite.py:647 Adding pre_mapping local_id=LocalID(inode=844424930197304L, volume='serial:3188545052'), doc_id=1EplMEKPojPbNMYrghvbVWSKlapuTgOC-
2021-07-21 18:38:39,042 +0900 ERROR pid=12760 12468:Worker-1        workers.py:234 Exception while processing change [FSChange(Direction.UPLOAD, Action.CREATE, local_id=LocalID(inode=844424930197304L, volume='serial:3188545052'), path=u'\\\\?\\C:\\workspace\\\ub179\ud654\\cakd3\\.git\\objects\\f5', name=u'0c1e325d869d51b59726f9f940a8c6262d1283', parent_local_id=LocalID(inode=844424930197303L, volume='serial:3188545052'), is_folder=False, modified=1625291484, size=5224, generator_module=Generator.LOCAL_EVENT_GENERATOR, shared=False, hash=-849481687, row_id=2113)]
Traceback (most recent call last):
  File "common\workers.py", line 201, in Process
  File "common\persistence\sqlite.py", line 141, in Wrapper
  File "common\workers.py", line 359, in _ProcessChanges
  File "common\worker\uploads.py", line 958, in Execute
  File "common\worker\uploads.py", line 1108, in _UploadCreate
  File "common\worker\workers_helper.py", line 406, in CreateCloudFile
  File "common\worker\workers_helper.py", line 372, in EnforceRemainingQuota
ClientDetectedCloudStorageQuotaExceeded: ClientDetectedCloudStorageQuotaExceeded: 'File size (5224) exceeds available space (-43553) on server.', recovery targets: set([])
2021-07-21 18:38:39,043 +0900 WARNING pid=12760 12468:Worker-1        workers.py:422 Setting recovery_targets for all changes. ClientDetectedCloudStorageQuotaExceeded: 'File size (5224) exceeds available space (-43553) on server.', recovery targets: set([])
2021-07-21 18:38:39,045 +0900 ERROR pid=12760 12468:Worker-1        fatal_exceptions.py:69 Ignoring non-fatal error: ClientDetectedCloudStorageQuotaExceeded: ClientDetectedCloudStorageQuotaExceeded: 'File size (5224) exceeds available space (-43553) on server.', recovery targets: set([LocalID(inode=844424930197304L, volume='serial:3188545052'), LocalID(inode=844424930197303L, volume='serial:3188545052')]), Traceback:
  File "common\workers.py", line 201, in Process
  File "common\persistence\sqlite.py", line 141, in Wrapper
  File "common\workers.py", line 359, in _ProcessChanges
  File "common\worker\uploads.py", line 958, in Execute
  File "common\worker\uploads.py", line 1108, in _UploadCreate
  File "common\worker\workers_helper.py", line 406, in CreateCloudFile
  File "common\worker\workers_helper.py", line 372, in EnforceRemainingQuota

2021-07-21 18:38:39,049 +0900 ERROR pid=12760 12460:Worker-2        blacklist.py:286 The following request has been blacklisted FSChange(Direction.UPLOAD, Action.CREATE, local_id=LocalID(inode=1125899906907962L, volume='serial:3188545052'), path=u'\\\\?\\C:\\workspace\\\ub179\ud654\\cakd3\\.git\\objects\\f5', name=u'ffcb4432db602e83d3d928213c6d5fd5a7216b', parent_local_id=LocalID(inode=844424930197303L, volume='serial:3188545052'), is_folder=False, modified=1626858110, size=18115, generator_module=Generator.LOCAL_EVENT_GENERATOR, shared=False, hash=-1657478157, row_id=2112) Because of exception: ClientDetectedCloudStorageQuotaExceeded: 'File size (18115) exceeds available space (-43553) on server.', recovery targets: set([LocalID(inode=844424930197303L, volume='serial:3188545052'), LocalID(inode=1125899906907962L, volume='serial:3188545052')])
2021-07-21 18:38:39,049 +0900 INFO pid=12760 12460:Worker-2        change_buffer_entry.py:215 Replacing entry in change buffer: ChangeBufferEntry(state=IN_PROGRESS, fschange=FSChange(Direction.UPLOAD, Action.CREATE, local_id=LocalID(inode=1125899906907962L, volume='serial:3188545052'), path=u'\\\\?\\C:\\workspace\\\ub179\ud654\\cakd3\\.git\\objects\\f5', name=u'ffcb4432db602e83d3d928213c6d5fd5a7216b', parent_local_id=LocalID(inode=844424930197303L, volume='serial:3188545052'), is_folder=False, modified=1626858110, size=18115, generator_module=Generator.LOCAL_EVENT_GENERATOR, shared=False, row_id=2112), time=190561.703, row_id=1925)->ChangeBufferEntry(state=BLACKLISTED, fschange=FSChange(Direction.UPLOAD, Action.CREATE, local_id=LocalID(inode=1125899906907962L, volume='serial:3188545052'), path=u'\\\\?\\C:\\workspace\\\ub179\ud654\\cakd3\\.git\\objects\\f5', name=u'ffcb4432db602e83d3d928213c6d5fd5a7216b', parent_local_id=LocalID(inode=844424930197303L, volume='serial:3188545052'), is_folder=False, modified=1626858110, size=18115, generator_module=Generator.LOCAL_EVENT_GENERATOR, shared=False, row_id=2112), blacklist_info=BlacklistInfoSub(key=u'\\\\?\\C:\\workspace\\\ub179\ud654\\cakd3\\.git\\objects\\f5\\ffcb4432db602e83d3d928213c6d5fd5a7216b', fullname=u'\\\\?\\C:\\workspace\\\ub179\ud654\\cakd3\\.git\\objects\\f5\\ffcb4432db602e83d3d928213c6d5fd5a7216b', direction=<Direction.UPLOAD: 'UPLOAD'>, failure=ClientDetectedCloudStorageQuotaExceeded(), entry_time=190692.046, url=None, is_folder=False, action=<Action.CREATE: 'CREATE'>), time=190561.703, row_id=1925)
2021-07-21 18:38:39,092 +0900 ERROR pid=12760 12468:Worker-1        blacklist.py:286 The following request has been blacklisted FSChange(Direction.UPLOAD, Action.CREATE, local_id=LocalID(inode=844424930197304L, volume='serial:3188545052'), path=u'\\\\?\\C:\\workspace\\\ub179\ud654\\cakd3\\.git\\objects\\f5', name=u'0c1e325d869d51b59726f9f940a8c6262d1283', parent_local_id=LocalID(inode=844424930197303L, volume='serial:3188545052'), is_folder=False, modified=1625291484, size=5224, generator_module=Generator.LOCAL_EVENT_GENERATOR, shared=False, hash=-849481687, row_id=2113) Because of exception: ClientDetectedCloudStorageQuotaExceeded: 'File size (5224) exceeds available space (-43553) on server.', recovery targets: set([LocalID(inode=844424930197304L, volume='serial:3188545052'), LocalID(inode=844424930197303L, volume='serial:3188545052')])
2021-07-21 18:38:39,092 +0900 INFO pid=12760 12468:Worker-1        change_buffer_entry.py:215 Replacing entry in change buffer: ChangeBufferEntry(state=IN_PROGRESS, fschange=FSChange(Direction.UPLOAD, Action.CREATE, local_id=LocalID(inode=844424930197304L, volume='serial:3188545052'), path=u'\\\\?\\C:\\workspace\\\ub179\ud654\\cakd3\\.git\\objects\\f5', name=u'0c1e325d869d51b59726f9f940a8c6262d1283', parent_local_id=LocalID(inode=844424930197303L, volume='serial:3188545052'), is_folder=False, modified=1625291484, size=5224, generator_module=Generator.LOCAL_EVENT_GENERATOR, shared=False, row_id=2113), time=190561.718, row_id=1926)->ChangeBufferEntry(state=BLACKLISTED, fschange=FSChange(Direction.UPLOAD, Action.CREATE, local_id=LocalID(inode=844424930197304L, volume='serial:3188545052'), path=u'\\\\?\\C:\\workspace\\\ub179\ud654\\cakd3\\.git\\objects\\f5', name=u'0c1e325d869d51b59726f9f940a8c6262d1283', parent_local_id=LocalID(inode=844424930197303L, volume='serial:3188545052'), is_folder=False, modified=1625291484, size=5224, generator_module=Generator.LOCAL_EVENT_GENERATOR, shared=False, row_id=2113), blacklist_info=BlacklistInfoSub(key=u'\\\\?\\C:\\workspace\\\ub179\ud654\\cakd3\\.git\\objects\\f5\\0c1e325d869d51b59726f9f940a8c6262d1283', fullname=u'\\\\?\\C:\\workspace\\\ub179\ud654\\cakd3\\.git\\objects\\f5\\0c1e325d869d51b59726f9f940a8c6262d1283', direction=<Direction.UPLOAD: 'UPLOAD'>, failure=ClientDetectedCloudStorageQuotaExceeded(), entry_time=190692.093, url=None, is_folder=False, action=<Action.CREATE: 'CREATE'>), time=190561.718, row_id=1926)
2021-07-21 18:38:39,154 +0900 INFO pid=12760 10252:Worker-0        workers.py:192 Worker starting on [FSChange(Direction.UPLOAD, Action.CREATE, local_id=LocalID(inode=844424930197305L, volume='serial:3188545052'), path=u'\\\\?\\C:\\workspace\\\ub179\ud654\\cakd3\\.git\\objects\\f5', name=u'9847fa43e453a1f9fad0b02fa223732d7bf8c3', parent_local_id=LocalID(inode=844424930197303L, volume='serial:3188545052'), is_folder=False, modifi